Workbook

Sheet Parameter
A1: Parameter | B1: Nilai / Angka | C1: Satuan | D1: Keterangan | F1: Faktor Evaluasi Jabatan | G1: Minimum | H1: Maksimal | I1: Bobot (%) | K1: Divisi | L1: Departemen | M1: Level
A2: UMK / Upah Minimum | B2: 5728878 | C2: IDR | D2: Wajib di update setiap tahun mengikuti pemerintah | F2: Pendidikan Formal | G2: =MIN(Pendidikan[Formula]) -> 50 | H2: =MAX(Pendidikan[]) -> 250 | I2: =H2/$H$8 -> 0.20833333 | K2: Commercial & Marketing | L2: Sales | M2: Administrator
A3: Progression Rate Antar Midpoint | B3: 0.06 | C3: Persen | D3: Kenaikan Midpoint dari satu Grade ke Grade berikutnya (6%) | F3: Pengalaman Kerja | G3: =MIN(Pengalaman[]) -> 50 | H3: =MAX(Pengalaman[]) -> 250 | I3: =H3/$H$8 -> 0.20833333 | K3: Human Resources | L3: Human Resources & General Affairs | M3: Administrator
A4: Salary Spread (Rentang Upah) | B4: 0.3 | C4: Persen | D4: Batas Minimum (85% Mid) hingga Maximum (115% Mid) | F4: Tanggung Jawab | G4: =MIN(TanggungJawab[]) -> 40 | H4: =MAX(TanggungJawab[]) -> 200 | I4: =H4/$H$8 -> 0.16666667 | K4: Management | L4: Accounting | M4: Administrator
A5: Rasio Upah Pokok | B5: 0.75 | C5: Persen | D5: Porsi Gaji Pokok dari Total Upah Tetap | F5: Problem Solving | G5: =MIN(ProblemSolving[]) -> 30 | H5: =MAX(ProblemSolving[]) -> 150 | I5: =H5/$H$8 -> 0.125 | K5: Management | L5: TAX | M5: Administrator
A6: Rasio Tunjangan Tetap | B6: 0.25 | C6: Persen | D6: Porsi Tunjangan Jabatan/Tetap dari Total Upah Tetap | F6: Leadership / Kepemimpinan | G6: =MIN(Leadership[]) -> 40 | H6: =MAX(Leadership[]) -> 200 | I6: =H6/$H$8 -> 0.16666667 | K6: Management | L6: Finance | M6: Administrator
F7: Komunikasi | G7: =MIN(Komunikasi[]) -> 30 | H7: =MAX(Komunikasi[]) -> 150 | I7: =H7/$H$8 -> 0.125 | K7: Manufacturing | L7: Production | M7: Administrator
A8: Pendidikan | B8: Formula | F8: TOTAL | G8: =SUM(G2:G7) -> 240 | H8: =SUM(H2:H7) -> 1200 | I8: =H8/$H$8 -> 1 | K8: Supply Chain Management | L8: Warehouse | M8: Administrator
A9: SMA / SMK / Sederajat | B9: 50 | K9: Supply Chain Management | L9: Purchasing | M9: Administrator
A10: Diploma 3 (D3) | B10: 100 | F10: Grade | G10: Level | H10: Minimal | I10: Maksimal | K10: Supply Chain Management | L10: PPIC | M10: Administrator
A11: Sarjana / Bachelor (S1) | B11: 150 | F11: G01 | G11: Operator | H11: =$G$8 -> 240 | I11: =ROUNDUP($G$8+(($H$8-$G$8)/9),0) -> 347 | K11: Management | L11: Finance | M11: General Manager
A12: Magister / Master (S2) | B12: 200 | F12: G02 | G12: Administrator | H12: =I11+1 -> 348 | I12: =ROUNDUP(H12+(($H$8-$G$8)/9),0) -> 455 | K12: Manufacturing | L12: Production | M12: Staff
A13: Doktor (S3) | B13: 250 | F13: G03 | G13: Staff | H13: =I12+1 -> 456 | I13: =ROUNDUP(H13+(($H$8-$G$8)/9),0) -> 563 | K13: Supply Chain Management | L13: Warehouse | M13: Staff
F14: G04 | G14: Senior Professional / Engineer / Analyst | H14: =I13+1 -> 564 | I14: =ROUNDUP(H14+(($H$8-$G$8)/9),0) -> 671 | K14: Commercial & Marketing | L14: Sales | M14: Manager
A15: Pengalaman | B15: Formula | F15: G05 | G15: Officer / Executive | H15: =I14+1 -> 672 | I15: =ROUNDUP(H15+(($H$8-$G$8)/9),0) -> 779 | K15: Corporate Governance | L15: Nomination & Remuneration Committee | M15: Manager
A16: Fresh Graduate < 1 Tahun | B16: 50 | F16: G06 | G16: Supervisor | H16: =I15+1 -> 780 | I16: =ROUNDUP(H16+(($H$8-$G$8)/9),0) -> 887 | K16: Human Resources | L16: Human Resources & General Affairs | M16: Manager
A17: 1 - 3 Tahun Pengalaman | B17: 100 | F17: G07 | G17: Manager | H17: =I16+1 -> 888 | I17: =ROUNDUP(H17+(($H$8-$G$8)/9),0) -> 995 | K17: Information Technology | L17: Information Technology | M17: Manager
A18: 3 - 5 Tahun Pengalaman | B18: 150 | F18: G08 | G18: General Manager | H18: =I17+1 -> 996 | I18: =ROUNDUP(H18+(($H$8-$G$8)/9),0) -> 1103 | K18: Legal & Compliance | L18: Legal | M18: Manager
A19: 5 - 8 Tahun Pengalaman | B19: 200 | F19: G09 | G19: Director | H19: =I18+1 -> 1104 | I19: =$H$8 -> 1200 | K19: Management | L19: Finance | M19: Manager
A20: > 8 Tahun Pengalaman | B20: 250 | K20: Manufacturing | L20: Quality Engineering | M20: Manager
F21: Grade | G21: Level | K21: Manufacturing | L21: Quality Assurance | M21: Manager
A22: Tanggung Jawab | B22: Formula | F22: G01 | G22: Operator | K22: Manufacturing | L22: Production | M22: Manager
A23: Tugas Rutin Dasar | B23: =1 * 40 -> 40 | F23: G02 | G23: Administrator | K23: Supply Chain Management | L23: Warehouse | M23: Manager
A24: Tugas Operasional Mandiri | B24: =2 * 40 -> 80 | F24: G03 | G24: Staff | K24: Supply Chain Management | L24: Purchasing | M24: Manager
A25: Pengawasan tim & sub-unit | B25: =3 * 40 -> 120 | F25: G04 | G25: Senior Professional / Engineer / Analyst | K25: Commercial & Marketing | L25: Sales | M25: Officer / Executive
A26: Pengelolaan anggaran & kinerja | B26: =4 * 40 -> 160 | F26: G05 | G26: Officer / Executive | K26: Commercial & Marketing | L26: Marketing | M26: Officer / Executive
A27: Penentuan arah strategis | B27: =5 * 40 -> 200 | F27: G06 | G27: Supervisor | K27: Human Resources | L27: Human Resources & General Affairs | M27: Officer / Executive
F28: G07 | G28: Manager | K28: Information Technology | L28: Information Technology | M28: Officer / Executive
A29: Problem Solving | B29: Formula | F29: G08 | G29: General Manager | K29: Legal & Compliance | L29: Legal | M29: Officer / Executive
A30: Sederhana & sesuai SOP | B30: =1*30 -> 30 | F30: G09 | G30: Director | K30: Management | L30: Accounting | M30: Officer / Executive
A31: Rutin & butuh pilah data | B31: =2*30 -> 60 | K31: Management | L31: TAX | M31: Officer / Executive
A32: Teknis kompleks & butuh analisis | B32: =3*30 -> 90 | K32: Supply Chain Management | L32: Purchasing | M32: Officer / Executive
A33: Strategis & belum ada preseden | B33: =4*30 -> 120 | K33: Supply Chain Management | L33: PPIC | M33: Officer / Executive
A34: Korporat & butuh inovasi | B34: =5*30 -> 150 | K34: Manufacturing | L34: Quality Assurance | M34: Operator
K35: Manufacturing | L35: Quality Engineering | M35: Operator
A36: Leadership | B36: Formula | K36: Manufacturing | L36: Production | M36: Operator
A37: Memberikan arahan kepada tim | B37: =1*40 -> 40 | K37: Supply Chain Management | L37: Warehouse | M37: Operator
A38: Mengambil keputusan operasional rutin | B38: =2*40 -> 80 | K38: Information Technology | L38: Information Technology | M38: Senior Professional / Engineer / Analyst
A39: Pengendalian alokasi & evaluasi sta | B39: =3*40 -> 120 | K39: Supply Chain Management | L39: PPIC | M39: Senior Professional / Engineer / Analyst
A40: Memimpin departemen / Manager | B40: =4*40 -> 160 | K40: Commercial & Marketing | L40: Marketing | M40: Staff
...

Sheet Job Grade
A1: Divisi | B1: Departemen | C1: Level | D1: Pendidikan | E1: Pengalaman | F1: Tanggung Jawab | G1: Problem Solving | H1: Leadership | I1: Komunikasi | J1: Total Poin | K1: Grade
A2: Commercial & Marketing | B2: Sales | C2: Administrator | D2: 100 | E2: 50 | F2: 40 | G2: 30 | H2: 0 | I2: 30 | J2: =SUM(D2:I2) -> 250 | K2: =_xlfn.XLOOKUP(J2,Parameter!$H$11:$H$19,Parameter!$F$11:$F$19,"",-1) -> G01
A3: Commercial & Marketing | B3: Sales | C3: Manager | D3: 150 | E3: 200 | F3: 200 | G3: 150 | H3: 160 | I3: 120 | J3: =SUM(D3:I3) -> 980 | K3: =_xlfn.XLOOKUP(J3,Parameter!$H$11:$H$19,Parameter!$F$11:$F$19,"",-1) -> G07
A4: Commercial & Marketing | B4: Sales | C4: Officer / Executive | D4: 150 | E4: 150 | F4: 120 | G4: 60 | H4: 40 | I4: 30 | J4: =SUM(D4:I4) -> 550 | K4: =_xlfn.XLOOKUP(J4,Parameter!$H$11:$H$19,Parameter!$F$11:$F$19,"",-1) -> G03
A5: Commercial & Marketing | B5: Marketing | C5: Officer / Executive | D5: 150 | E5: 150 | F5: 120 | G5: 60 | H5: 40 | I5: 30 | J5: =SUM(D5:I5) -> 550 | K5: =_xlfn.XLOOKUP(J5,Parameter!$H$11:$H$19,Parameter!$F$11:$F$19,"",-1) -> G03
A6: Commercial & Marketing | B6: Marketing | C6: Staff | D6: 100 | E6: 100 | F6: 80 | G6: 60 | H6: 0 | I6: 30 | J6: =SUM(D6:I6) -> 370 | K6: =_xlfn.XLOOKUP(J6,Parameter!$H$11:$H$19,Parameter!$F$11:$F$19,"",-1) -> G02
A7: Commercial & Marketing | B7: Sales | C7: Supervisor | D7: 150 | E7: 150 | F7: 120 | G7: 120 | H7: 120 | I7: 30 | J7: =SUM(D7:I7) -> 690 | K7: =_xlfn.XLOOKUP(J7,Parameter!$H$11:$H$19,Parameter!$F$11:$F$19,"",-1) -> G05
A8: Commercial & Marketing | B8: Marketing | C8: Supervisor | D8: 150 | E8: 150 | F8: 120 | G8: 120 | H8: 120 | I8: 30 | J8: =SUM(D8:I8) -> 690 | K8: =_xlfn.XLOOKUP(J8,Parameter!$H$11:$H$19,Parameter!$F$11:$F$19,"",-1) -> G05
A9: Corporate Governance | B9: Nomination & Remuneration Committee | C9: Manager | D9: 150 | E9: 200 | F9: 200 | G9: 150 | H9: 160 | I9: 90 | J9: =SUM(D9:I9) -> 950 | K9: =_xlfn.XLOOKUP(J9,Parameter!$H$11:$H$19,Parameter!$F$11:$F$19,"",-1) -> G07
A10: Corporate Governance | B10: Nomination & Remuneration Committee | C10: Staff | D10: 100 | E10: 100 | F10: 80 | G10: 60 | H10: 0 | I10: 30 | J10: =SUM(D10:I10) -> 370 | K10: =_xlfn.XLOOKUP(J10,Parameter!$H$11:$H$19,Parameter!$F$11:$F$19,"",-1) -> G02
A11: Human Resources | B11: Human Resources & General Affairs | C11: Administrator | D11: 100 | E11: 50 | F11: 40 | G11: 30 | H11: 0 | I11: 30 | J11: =SUM(D11:I11) -> 250 | K11: =_xlfn.XLOOKUP(J11,Parameter!$H$11:$H$19,Parameter!$F$11:$F$19,"",-1) -> G01
A12: Human Resources | B12: Human Resources & General Affairs | C12: Manager | D12: 150 | E12: 200 | F12: 200 | G12: 150 | H12: 160 | I12: 30 | J12: =SUM(D12:I12) -> 890 | K12: =_xlfn.XLOOKUP(J12,Parameter!$H$11:$H$19,Parameter!$F$11:$F$19,"",-1) -> G07
A13: Human Resources | B13: Human Resources & General Affairs | C13: Officer / Executive | D13: 150 | E13: 150 | F13: 120 | G13: 60 | H13: 40 | I13: 30 | J13: =SUM(D13:I13) -> 550 | K13: =_xlfn.XLOOKUP(J13,Parameter!$H$11:$H$19,Parameter!$F$11:$F$19,"",-1) -> G03
... A62: Supply Chain Management | B62: PPIC | C62: Supervisor | D62: 150 | E62: 150 | F62: 120 | G62: 120 | H62: 120 | I62: 30 | J62: =SUM(D62:I62) -> 690 | K62: =_xlfn.XLOOKUP(J62,Parameter!$H$11:$H$19,Parameter!$F$11:$F$19,"",-1) -> G05

Sheet Structure
A1: Grade | B1: Level | C1: Minimal | D1: Midpoin | E1: Maximial | F1: Mid GP (75%) | G1: MidTunjangan (25%) | H1: Subtotal
A2: G01 | B2: =VLOOKUP(Table13[[#This Row],[Grade]],Grade[],2) -> Operator | C2: =Table1[[#This Row],[Nilai / Angka]] -> 5728878 | D2: =C2*(1+(0.5*Parameter!$B$4)) -> 6588209.7 | E2: =C2*(1+Parameter!$B$4) -> 7447541.4 | F2: =C2*Parameter!$B$5 -> 4296658.5 | G2: =C2*Parameter!$B$6 -> 1432219.5 | H2: =SUM(Table13[[#This Row],[Mid GP (75%)]:[MidTunjangan (25%)]]) -> 5728878 | J2: =
A3: G02 | B3: =VLOOKUP(Table13[[#This Row],[Grade]],Grade[],2) -> Administrator | C3: =Parameter!B2 -> 5728878 | D3: =C3*(1+(0.5*Parameter!$B$4)) -> 6588209.7 | E3: =C3*(1+Parameter!$B$4) -> 7447541.4 | F3: =C3*Parameter!$B$5 -> 4296658.5 | G3: =C3*Parameter!$B$6 -> 1432219.5 | H3: =SUM(Table13[[#This Row],[Mid GP (75%)]:[MidTunjangan (25%)]]) -> 5728878
A4: G03 | B4: =VLOOKUP(Table13[[#This Row],[Grade]],Grade[],2) -> Staff | C4: =D3*(1+Parameter!$B$3)/(1+(0.5*Parameter!$B$4)) -> 6072610.7 | D4: =C4*(1+(0.5*Parameter!$B$4)) -> 6983502.3 | E4: =C4*(1+Parameter!$B$4) -> 7894393.9 | F4: =D4*Parameter!$B$5 -> 5237626.7 | G4: =D4*Parameter!$B$6 -> 1745875.6 | H4: =SUM(Table13[[#This Row],[Mid GP (75%)]:[MidTunjangan (25%)]]) -> 6983502.3
A5: G04 | B5: =VLOOKUP(Table13[[#This Row],[Grade]],Grade[],2) -> Senior Professional / Engineer / Analyst | C5: =D4*(1+Parameter!$B$3)/(1+(0.5*Parameter!$B$4)) -> 6436967.3 | D5: =C5*(1+(0.5*Parameter!$B$4)) -> 7402512.4 | E5: =C5*(1+Parameter!$B$4) -> 8368057.5 | F5: =D5*Parameter!$B$5 -> 5551884.3 | G5: =D5*Parameter!$B$6 -> 1850628.1 | H5: =SUM(Table13[[#This Row],[Mid GP (75%)]:[MidTunjangan (25%)]]) -> 7402512.4
A6: G05 | B6: =VLOOKUP(Table13[[#This Row],[Grade]],Grade[],2) -> Officer / Executive | C6: =D5*(1+Parameter!$B$3)/(1+(0.5*Parameter!$B$4)) -> 6823185.4 | D6: =C6*(1+(0.5*Parameter!$B$4)) -> 7846663.2 | E6: =C6*(1+Parameter!$B$4) -> 8870141 | F6: =D6*Parameter!$B$5 -> 5884997.4 | G6: =D6*Parameter!$B$6 -> 1961665.8 | H6: =SUM(Table13[[#This Row],[Mid GP (75%)]:[MidTunjangan (25%)]]) -> 7846663.2
A7: G06 | B7: =VLOOKUP(Table13[[#This Row],[Grade]],Grade[],2) -> Supervisor | C7: =D6*(1+Parameter!$B$3)/(1+(0.5*Parameter!$B$4)) -> 7232576.5 | D7: =C7*(1+(0.5*Parameter!$B$4)) -> 8317463 | E7: =C7*(1+Parameter!$B$4) -> 9402349.4 | F7: =D7*Parameter!$B$5 -> 6238097.2 | G7: =D7*Parameter!$B$6 -> 2079365.7 | H7: =SUM(Table13[[#This Row],[Mid GP (75%)]:[MidTunjangan (25%)]]) -> 8317463
A8: G07 | B8: =VLOOKUP(Table13[[#This Row],[Grade]],Grade[],2) -> Manager | C8: =D7*(1+Parameter!$B$3)/(1+(0.5*Parameter!$B$4)) -> 7666531.1 | D8: =C8*(1+(0.5*Parameter!$B$4)) -> 8816510.7 | E8: =C8*(1+Parameter!$B$4) -> 9966490.4 | F8: =D8*Parameter!$B$5 -> 6612383 | G8: =D8*Parameter!$B$6 -> 2204127.7 | H8: =SUM(Table13[[#This Row],[Mid GP (75%)]:[MidTunjangan (25%)]]) -> 8816510.7
A9: G08 | B9: =VLOOKUP(Table13[[#This Row],[Grade]],Grade[],2) -> General Manager | C9: =D8*(1+Parameter!$B$3)/(1+(0.5*Parameter!$B$4)) -> 8126522.9 | D9: =C9*(1+(0.5*Parameter!$B$4)) -> 9345501.4 | E9: =C9*(1+Parameter!$B$4) -> 10564480 | F9: =D9*Parameter!$B$5 -> 7009126 | G9: =D9*Parameter!$B$6 -> 2336375.3 | H9: =SUM(Table13[[#This Row],[Mid GP (75%)]:[MidTunjangan (25%)]]) -> 9345501.4
A10: G09 | B10: =VLOOKUP(Table13[[#This Row],[Grade]],Grade[],2) -> Director | C10: =D9*(1+Parameter!$B$3)/(1+(0.5*Parameter!$B$4)) -> 8614114.3 | D10: =C10*(1+(0.5*Parameter!$B$4)) -> 9906231.5 | E10: =C10*(1+Parameter!$B$4) -> 11198349 | F10: =D10*Parameter!$B$5 -> 7429673.6 | G10: =D10*Parameter!$B$6 -> 2476557.9 | H10: =SUM(Table13[[#This Row],[Mid GP (75%)]:[MidTunjangan (25%)]]) -> 9906231.5
