Workbook
Name Active: Reference!$R$2:$R$6
Name BachS1: Reference!$K$25:$K$39
Name DATA: 'Data Employee'!$A$2:$AG$247
Name Degree3: Reference!$K$10:$K$24
Name Dept_CM: Reference!$S$20:$S$21
Name Dept_Corporate: Reference!$S$31:$S$34
Name Dept_HRD: Reference!$S$19
Name Dept_IT: Reference!$S$28
Name Dept_Legal: Reference!$S$30
Name Dept_Management: Reference!$S$16:$S$18
Name Dept_MFG: Reference!$S$25:$S$27
Name Dept_RND: Reference!$S$29
Name Dept_SCM: Reference!$S$22:$S$24
Name Dept_TopMan: Reference!$S$35
Name DeptList: INDIRECT(_xlfn.XLOOKUP(INDEX('Data Employee'!$T:$T,ROW()),Reference!$AA$2:$AA$11,Reference!$AB$2:$AB$11))
Name DocS3: Reference!$K$55:$K$69
Name HighSchool: Reference!$K$2:$K$3
Name HR: Reference!$S$19
Name Pemotong_Divison: #N/A
Name Pemotong_Job_Level: #N/A
Name Range_Admin_ACC: Reference!$H$40
Name Range_Admin_FIN: Reference!$H$41
Name Range_Admin_HR: Reference!$H$19
Name Range_Admin_PPIC: Reference!$H$80:$H$81
Name Range_Admin_Prod: Reference!$H$54
Name Range_Admin_PURC: Reference!$H$82
Name Range_Admin_RND: Reference!$H$71
Name Range_Admin_Sales: Reference!$H$2
Name Range_Admin_TAX: Reference!$H$42
Name Range_Admin_WRHS: Reference!$H$83
Name Range_Analytst_IT: Reference!$H$31:$H$33
Name Range_Chairman: Reference!$H$12
Name Range_Commissioner: Reference!$H$13
Name Range_GM: Reference!$H$43
Name Range_Intern_HR: Reference!$H$20
Name Range_Intern_MAR: Reference!$H$3
Name Range_Intern_Prod: Reference!$H$55
Name Range_Intern_PURC: Reference!$H$84
Name Range_Intern_Sales: Reference!$H$4
Name Range_Intern_WRHS: Reference!$H$85
Name Range_Lead_Prod: Reference!$H$56:$H$57
Name Range_Lead_WRHS: Reference!$H$86
Name Range_MNGR_Audit: Reference!$H$14
Name Range_MNGR_FIN: Reference!$H$44
Name Range_MNGR_HR: Reference!$H$21
Name Range_MNGR_IT: Reference!$H$29
Name Range_MNGR_Legal: Reference!$H$39
Name Range_MNGR_MAR: Reference!$H$5
Name Range_MNGR_Nomi: Reference!$H$15
Name Range_MNGR_PPIC: Reference!$H$87
Name Range_MNGR_Prod: Reference!$H$58
Name Range_MNGR_PURC: Reference!$H$88
Name Range_MNGR_QA: Reference!$H$59
Name Range_MNGR_QE: Reference!$H$60
Name Range_MNGR_RND: Reference!$H$72
Name Range_MNGR_Sales: Reference!$H$6
Name Range_MNGR_WRHS: Reference!$H$89
Name Range_Officer_ACC: Reference!$H$45
Name Range_Officer_Corporate: Reference!$H$16
Name Range_Officer_FIN: Reference!$H$46

Sheet Dashboard
A1: HR METRICS PT. Dumi Bumi Tbk
A3: Created by Wahyudiansyah

Sheet Monitoring Contract
A1: Employee Number | B1: Full Name | C1: Gender | D1: No. Contract | E1: Duration (Month) | F1: Divison | G1: Departemen | H1: Job Title | I1: Job Level | J1: Join Date | K1: End Date | L1: Contract Balance | M1: Status Reminder
A2: 201743091 | B2: =INDEX('Data Employee'!$B$2:$B$1000, MATCH(A2, 'Data Employee'!$A$2:$A$1000, 0)) -> Dewi Pratama | C2: =INDEX('Data Employee'!$G$2:$G$1000,MATCH(A2,'Data Employee'!$A$2:$A$1000,0)) -> Female | D2: {=IF(J2="","",_xlfn.IFS(DATEDIF(J2,TODAY(),"M")<12,"Contract 1",DATEDIF(J2,TODAY(),"M")<36,"Contract 2",DATEDIF(J2,TODAY(),"M")<60,"Contract 3",DATEDIF(J2,TODAY(),"M")<63,"Probation",TRUE,"Permanent"))} -> Permanent | E2: =IF(D2="Permanent","Permanent",IF(D2="Contract 1","12 Month",IF(D2="Contract 2","24 Month",IF(D2="Contract 3","60 Month",IF(D2="Probation","63 Month",""))))) -> Permanent | F2: =VLOOKUP(A2, 'Data Employee'!$A$2:$U$1000, 19, FALSE) -> Accounting | G2: =VLOOKUP(A2, 'Data Employee'!$A$2:$U$1000, 20, FALSE) -> Management | H2: =INDEX('Data Employee'!$W$2:$W$1000, MATCH(A2, 'Data Employee'!$A$2:$A$1000, 0)) -> Accounting Officer | I2: =INDEX('Data Employee'!$V$2:$V$1000,MATCH(A2,'Data Employee'!$A$2:$A$1000,0)) -> Officer / Executive | J2: =INDEX('Data Employee'!$L$2:$L$1000, MATCH(A2, 'Data Employee'!$A$2:$A$1000, 0)) -> 43091 | K2: =IFERROR(IF(INDEX('Data Employee'!M:M,MATCH(A2,'Data Employee'!A:A,0))="","",INDEX('Data Employee'!M:M,MATCH(A2,'Data Employee'!A:A,0))),"") | L2: =IF(OR(K2="",K2<TODAY()),IF(K2="","","Expired"),DATEDIF(TODAY(),K2,"D")&" Days") | M2: =IF(OR(K2="", D2="Permanent", NOT(ISNUMBER(K2))), "Active", IF(K2<TODAY(), "Expired", IF(K2-TODAY()<=30, "Urgent Renewal", IF(K2-TODAY()<=60, "Review Needed", "Active")))) -> Active
A3: 201843228 | B3: =INDEX('Data Employee'!$B$2:$B$1000, MATCH(A3, 'Data Employee'!$A$2:$A$1000, 0)) -> Aulia Kurniawan | C3: =INDEX('Data Employee'!$G$2:$G$1000,MATCH(A3,'Data Employee'!$A$2:$A$1000,0)) -> Female | D3: {=IF(J3="","",_xlfn.IFS(DATEDIF(J3,TODAY(),"M")<12,"Contract 1",DATEDIF(J3,TODAY(),"M")<36,"Contract 2",DATEDIF(J3,TODAY(),"M")<60,"Contract 3",DATEDIF(J3,TODAY(),"M")<63,"Probation",TRUE,"Permanent"))} -> Permanent | E3: =IF(D3="Permanent","Permanent",IF(D3="Contract 1","12 Month",IF(D3="Contract 2","24 Month",IF(D3="Contract 3","60 Month",IF(D3="Probation","63 Month",""))))) -> Permanent | F3: =VLOOKUP(A3, 'Data Employee'!$A$2:$U$1000, 19, FALSE) -> Accounting | G3: =VLOOKUP(A3, 'Data Employee'!$A$2:$U$1000, 20, FALSE) -> Management | H3: =INDEX('Data Employee'!$W$2:$W$1000, MATCH(A3, 'Data Employee'!$A$2:$A$1000, 0)) -> Accounting Officer | I3: =INDEX('Data Employee'!$V$2:$V$1000,MATCH(A3,'Data Employee'!$A$2:$A$1000,0)) -> Officer / Executive | J3: =INDEX('Data Employee'!$L$2:$L$1000, MATCH(A3, 'Data Employee'!$A$2:$A$1000, 0)) -> 43228 | K3: =IFERROR(IF(INDEX('Data Employee'!M:M,MATCH(A3,'Data Employee'!A:A,0))="","",INDEX('Data Employee'!M:M,MATCH(A3,'Data Employee'!A:A,0))),"") | L3: =IF(OR(K3="",K3<TODAY()),IF(K3="","","Expired"),DATEDIF(TODAY(),K3,"D")&" Days") | M3: =IF(OR(K3="", D3="Permanent", NOT(ISNUMBER(K3))), "Active", IF(K3<TODAY(), "Expired", IF(K3-TODAY()<=30, "Urgent Renewal", IF(K3-TODAY()<=60, "Review Needed", "Active")))) -> Active
A4: 202043936 | B4: =INDEX('Data Employee'!$B$2:$B$1000, MATCH(A4, 'Data Employee'!$A$2:$A$1000, 0)) -> Putri Ramadhan | C4: =INDEX('Data Employee'!$G$2:$G$1000,MATCH(A4,'Data Employee'!$A$2:$A$1000,0)) -> Female | D4: {=IF(J4="","",_xlfn.IFS(DATEDIF(J4,TODAY(),"M")<12,"Contract 1",DATEDIF(J4,TODAY(),"M")<36,"Contract 2",DATEDIF(J4,TODAY(),"M")<60,"Contract 3",DATEDIF(J4,TODAY(),"M")<63,"Probation",TRUE,"Permanent"))} -> Contract 3 | E4: =IF(D4="Permanent","Permanent",IF(D4="Contract 1","12 Month",IF(D4="Contract 2","24 Month",IF(D4="Contract 3","60 Month",IF(D4="Probation","63 Month",""))))) -> 60 Month | F4: =VLOOKUP(A4, 'Data Employee'!$A$2:$U$1000, 19, FALSE) -> Accounting | G4: =VLOOKUP(A4, 'Data Employee'!$A$2:$U$1000, 20, FALSE) -> Management | H4: =INDEX('Data Employee'!$W$2:$W$1000, MATCH(A4, 'Data Employee'!$A$2:$A$1000, 0)) -> Accounting Staff | I4: =INDEX('Data Employee'!$V$2:$V$1000,MATCH(A4,'Data Employee'!$A$2:$A$1000,0)) -> Staff | J4: =INDEX('Data Employee'!$L$2:$L$1000, MATCH(A4, 'Data Employee'!$A$2:$A$1000, 0)) -> 45031 | K4: =IFERROR(IF(INDEX('Data Employee'!M:M,MATCH(A4,'Data Employee'!A:A,0))="","",INDEX('Data Employee'!M:M,MATCH(A4,'Data Employee'!A:A,0))),"") -> 46858 | L4: =IF(OR(K4="",K4<TODAY()),IF(K4="","","Expired"),DATEDIF(TODAY(),K4,"D")&" Days") -> 622 Days | M4: =IF(OR(K4="", D4="Permanent", NOT(ISNUMBER(K4))), "Active", IF(K4<TODAY(), "Expired", IF(K4-TODAY()<=30, "Urgent Renewal", IF(K4-TODAY()<=60, "Review Needed", "Active")))) -> Active
A5: 201743026 | B5: =INDEX('Data Employee'!$B$2:$B$1000, MATCH(A5, 'Data Employee'!$A$2:$A$1000, 0)) -> Indah Wijaya | C5: =INDEX('Data Employee'!$G$2:$G$1000,MATCH(A5,'Data Employee'!$A$2:$A$1000,0)) -> Female | D5: {=IF(J5="","",_xlfn.IFS(DATEDIF(J5,TODAY(),"M")<12,"Contract 1",DATEDIF(J5,TODAY(),"M")<36,"Contract 2",DATEDIF(J5,TODAY(),"M")<60,"Contract 3",DATEDIF(J5,TODAY(),"M")<63,"Probation",TRUE,"Permanent"))} -> Contract 2 | E5: =IF(D5="Permanent","Permanent",IF(D5="Contract 1","12 Month",IF(D5="Contract 2","24 Month",IF(D5="Contract 3","60 Month",IF(D5="Probation","63 Month",""))))) -> 24 Month | F5: =VLOOKUP(A5, 'Data Employee'!$A$2:$U$1000, 19, FALSE) -> Economics | G5: =VLOOKUP(A5, 'Data Employee'!$A$2:$U$1000, 20, FALSE) -> Management | H5: =INDEX('Data Employee'!$W$2:$W$1000, MATCH(A5, 'Data Employee'!$A$2:$A$1000, 0)) -> Accounting Staff | I5: =INDEX('Data Employee'!$V$2:$V$1000,MATCH(A5,'Data Employee'!$A$2:$A$1000,0)) -> Staff | J5: =INDEX('Data Employee'!$L$2:$L$1000, MATCH(A5, 'Data Employee'!$A$2:$A$1000, 0)) -> 45583 | K5: =IFERROR(IF(INDEX('Data Employee'!M:M,MATCH(A5,'Data Employee'!A:A,0))="","",INDEX('Data Employee'!M:M,MATCH(A5,'Data Employee'!A:A,0))),"") -> 47409 | L5: =IF(OR(K5="",K5<TODAY()),IF(K5="","","Expired"),DATEDIF(TODAY(),K5,"D")&" Days") -> 1173 Days | M5: =IF(OR(K5="", D5="Permanent", NOT(ISNUMBER(K5))), "Active", IF(K5<TODAY(), "Expired", IF(K5-TODAY()<=30, "Urgent Renewal", IF(K5-TODAY()<=60, "Review Needed", "Active")))) -> Active
A6: 201642668 | B6: =INDEX('Data Employee'!$B$2:$B$1000, MATCH(A6, 'Data Employee'!$A$2:$A$1000, 0)) -> Yulia Kurniawan | C6: =INDEX('Data Employee'!$G$2:$G$1000,MATCH(A6,'Data Employee'!$A$2:$A$1000,0)) -> Female | D6: {=IF(J6="","",_xlfn.IFS(DATEDIF(J6,TODAY(),"M")<12,"Contract 1",DATEDIF(J6,TODAY(),"M")<36,"Contract 2",DATEDIF(J6,TODAY(),"M")<60,"Contract 3",DATEDIF(J6,TODAY(),"M")<63,"Probation",TRUE,"Permanent"))} -> Contract 3 | E6: =IF(D6="Permanent","Permanent",IF(D6="Contract 1","12 Month",IF(D6="Contract 2","24 Month",IF(D6="Contract 3","60 Month",IF(D6="Probation","63 Month",""))))) -> 60 Month | F6: =VLOOKUP(A6, 'Data Employee'!$A$2:$U$1000, 19, FALSE) -> Business Administration | G6: =VLOOKUP(A6, 'Data Employee'!$A$2:$U$1000, 20, FALSE) -> Management | H6: =INDEX('Data Employee'!$W$2:$W$1000, MATCH(A6, 'Data Employee'!$A$2:$A$1000, 0)) -> Accounting Administration Staff | I6: =INDEX('Data Employee'!$V$2:$V$1000,MATCH(A6,'Data Employee'!$A$2:$A$1000,0)) -> Administrator | J6: =INDEX('Data Employee'!$L$2:$L$1000, MATCH(A6, 'Data Employee'!$A$2:$A$1000, 0)) -> 44494 | K6: =IFERROR(IF(INDEX('Data Employee'!M:M,MATCH(A6,'Data Employee'!A:A,0))="","",INDEX('Data Employee'!M:M,MATCH(A6,'Data Employee'!A:A,0))),"") -> 46412 | L6: =IF(OR(K6="",K6<TODAY()),IF(K6="","","Expired"),DATEDIF(TODAY(),K6,"D")&" Days") -> 176 Days | M6: =IF(OR(K6="", D6="Permanent", NOT(ISNUMBER(K6))), "Active", IF(K6<TODAY(), "Expired", IF(K6-TODAY()<=30, "Urgent Renewal", IF(K6-TODAY()<=60, "Review Needed", "Active")))) -> Active
A7: 201843210 | B7: =INDEX('Data Employee'!$B$2:$B$1000, MATCH(A7, 'Data Employee'!$A$2:$A$1000, 0)) -> Rudi Saputra | C7: =INDEX('Data Employee'!$G$2:$G$1000,MATCH(A7,'Data Employee'!$A$2:$A$1000,0)) -> Male | D7: {=IF(J7="","",_xlfn.IFS(DATEDIF(J7,TODAY(),"M")<12,"Contract 1",DATEDIF(J7,TODAY(),"M")<36,"Contract 2",DATEDIF(J7,TODAY(),"M")<60,"Contract 3",DATEDIF(J7,TODAY(),"M")<63,"Probation",TRUE,"Permanent"))} -> Permanent | E7: =IF(D7="Permanent","Permanent",IF(D7="Contract 1","12 Month",IF(D7="Contract 2","24 Month",IF(D7="Contract 3","60 Month",IF(D7="Probation","63 Month",""))))) -> Permanent | F7: =VLOOKUP(A7, 'Data Employee'!$A$2:$U$1000, 19, FALSE) -> Accounting | G7: =VLOOKUP(A7, 'Data Employee'!$A$2:$U$1000, 20, FALSE) -> Management | H7: =INDEX('Data Employee'!$W$2:$W$1000, MATCH(A7, 'Data Employee'!$A$2:$A$1000, 0)) -> Accounting Supervisor | I7: =INDEX('Data Employee'!$V$2:$V$1000,MATCH(A7,'Data Employee'!$A$2:$A$1000,0)) -> Supervisor | J7: =INDEX('Data Employee'!$L$2:$L$1000, MATCH(A7, 'Data Employee'!$A$2:$A$1000, 0)) -> 43210 | K7: =IFERROR(IF(INDEX('Data Employee'!M:M,MATCH(A7,'Data Employee'!A:A,0))="","",INDEX('Data Employee'!M:M,MATCH(A7,'Data Employee'!A:A,0))),"") | L7: =IF(OR(K7="",K7<TODAY()),IF(K7="","","Expired"),DATEDIF(TODAY(),K7,"D")&" Days") | M7: =IF(OR(K7="", D7="Permanent", NOT(ISNUMBER(K7))), "Active", IF(K7<TODAY(), "Expired", IF(K7-TODAY()<=30, "Urgent Renewal", IF(K7-TODAY()<=60, "Review Needed", "Active")))) -> Active
A8: 202043917 | B8: =INDEX('Data Employee'!$B$2:$B$1000, MATCH(A8, 'Data Employee'!$A$2:$A$1000, 0)) -> Nadia Wijaya | C8: =INDEX('Data Employee'!$G$2:$G$1000,MATCH(A8,'Data Employee'!$A$2:$A$1000,0)) -> Female | D8: {=IF(J8="","",_xlfn.IFS(DATEDIF(J8,TODAY(),"M")<12,"Contract 1",DATEDIF(J8,TODAY(),"M")<36,"Contract 2",DATEDIF(J8,TODAY(),"M")<60,"Contract 3",DATEDIF(J8,TODAY(),"M")<63,"Probation",TRUE,"Permanent"))} -> Permanent | E8: =IF(D8="Permanent","Permanent",IF(D8="Contract 1","12 Month",IF(D8="Contract 2","24 Month",IF(D8="Contract 3","60 Month",IF(D8="Probation","63 Month",""))))) -> Permanent | F8: =VLOOKUP(A8, 'Data Employee'!$A$2:$U$1000, 19, FALSE) -> Accounting | G8: =VLOOKUP(A8, 'Data Employee'!$A$2:$U$1000, 20, FALSE) -> Corporate Governance | H8: =INDEX('Data Employee'!$W$2:$W$1000, MATCH(A8, 'Data Employee'!$A$2:$A$1000, 0)) -> Audit Committee Staff | I8: =INDEX('Data Employee'!$V$2:$V$1000,MATCH(A8,'Data Employee'!$A$2:$A$1000,0)) -> Staff | J8: =INDEX('Data Employee'!$L$2:$L$1000, MATCH(A8, 'Data Employee'!$A$2:$A$1000, 0)) -> 43186 | K8: =IFERROR(IF(INDEX('Data Employee'!M:M,MATCH(A8,'Data Employee'!A:A,0))="","",INDEX('Data Employee'!M:M,MATCH(A8,'Data Employee'!A:A,0))),"") | L8: =IF(OR(K8="",K8<TODAY()),IF(K8="","","Expired"),DATEDIF(TODAY(),K8,"D")&" Days") | M8: =IF(OR(K8="", D8="Permanent", NOT(ISNUMBER(K8))), "Active", IF(K8<TODAY(), "Expired", IF(K8-TODAY()<=30, "Urgent Renewal", IF(K8-TODAY()<=60, "Review Needed", "Active")))) -> Active
A9: 201642597 | B9: =INDEX('Data Employee'!$B$2:$B$1000, MATCH(A9, 'Data Employee'!$A$2:$A$1000, 0)) -> Dedi Wijaya | C9: =INDEX('Data Employee'!$G$2:$G$1000,MATCH(A9,'Data Employee'!$A$2:$A$1000,0)) -> Male | D9: {=IF(J9="","",_xlfn.IFS(DATEDIF(J9,TODAY(),"M")<12,"Contract 1",DATEDIF(J9,TODAY(),"M")<36,"Contract 2",DATEDIF(J9,TODAY(),"M")<60,"Contract 3",DATEDIF(J9,TODAY(),"M")<63,"Probation",TRUE,"Permanent"))} -> Permanent | E9: =IF(D9="Permanent","Permanent",IF(D9="Contract 1","12 Month",IF(D9="Contract 2","24 Month",IF(D9="Contract 3","60 Month",IF(D9="Probation","63 Month",""))))) -> Permanent | F9: =VLOOKUP(A9, 'Data Employee'!$A$2:$U$1000, 19, FALSE) -> Accounting | G9: =VLOOKUP(A9, 'Data Employee'!$A$2:$U$1000, 20, FALSE) -> Corporate Governance | H9: =INDEX('Data Employee'!$W$2:$W$1000, MATCH(A9, 'Data Employee'!$A$2:$A$1000, 0)) -> Audit Committee Manager | I9: =INDEX('Data Employee'!$V$2:$V$1000,MATCH(A9,'Data Employee'!$A$2:$A$1000,0)) -> Manager | J9: =INDEX('Data Employee'!$L$2:$L$1000, MATCH(A9, 'Data Employee'!$A$2:$A$1000, 0)) -> 42597 | K9: =IFERROR(IF(INDEX('Data Employee'!M:M,MATCH(A9,'Data Employee'!A:A,0))="","",INDEX('Data Employee'!M:M,MATCH(A9,'Data Employee'!A:A,0))),"") | L9: =IF(OR(K9="",K9<TODAY()),IF(K9="","","Expired"),DATEDIF(TODAY(),K9,"D")&" Days") | M9: =IF(OR(K9="", D9="Permanent", NOT(ISNUMBER(K9))), "Active", IF(K9<TODAY(), "Expired", IF(K9-TODAY()<=30, "Urgent Renewal", IF(K9-TODAY()<=60, "Review Needed", "Active")))) -> Active
A10: 202043908 | B10: =INDEX('Data Employee'!$B$2:$B$1000, MATCH(A10, 'Data Employee'!$A$2:$A$1000, 0)) -> Andi Ramadhan | C10: =INDEX('Data Employee'!$G$2:$G$1000,MATCH(A10,'Data Employee'!$A$2:$A$1000,0)) -> Male | D10: {=IF(J10="","",_xlfn.IFS(DATEDIF(J10,TODAY(),"M")<12,"Contract 1",DATEDIF(J10,TODAY(),"M")<36,"Contract 2",DATEDIF(J10,TODAY(),"M")<60,"Contract 3",DATEDIF(J10,TODAY(),"M")<63,"Probation",TRUE,"Permanent"))} -> Permanent | E10: =IF(D10="Permanent","Permanent",IF(D10="Contract 1","12 Month",IF(D10="Contract 2","24 Month",IF(D10="Contract 3","60 Month",IF(D10="Probation","63 Month",""))))) -> Permanent | F10: =VLOOKUP(A10, 'Data Employee'!$A$2:$U$1000, 19, FALSE) -> Management | G10: =VLOOKUP(A10, 'Data Employee'!$A$2:$U$1000, 20, FALSE) -> Corporate Governance | H10: =INDEX('Data Employee'!$W$2:$W$1000, MATCH(A10, 'Data Employee'!$A$2:$A$1000, 0)) -> Audit Committee Staff | I10: =INDEX('Data Employee'!$V$2:$V$1000,MATCH(A10,'Data Employee'!$A$2:$A$1000,0)) -> Staff | J10: =INDEX('Data Employee'!$L$2:$L$1000, MATCH(A10, 'Data Employee'!$A$2:$A$1000, 0)) -> 43542 | K10: =IFERROR(IF(INDEX('Data Employee'!M:M,MATCH(A10,'Data Employee'!A:A,0))="","",INDEX('Data Employee'!M:M,MATCH(A10,'Data Employee'!A:A,0))),"") | L10: =IF(OR(K10="",K10<TODAY()),IF(K10="","","Expired"),DATEDIF(TODAY(),K10,"D")&" Days") | M10: =IF(OR(K10="", D10="Permanent", NOT(ISNUMBER(K10))), "Active", IF(K10<TODAY(), "Expired", IF(K10-TODAY()<=30, "Urgent Renewal", IF(K10-TODAY()<=60, "Review Needed", "Active")))) -> Active
A11: 202043954 | B11: =INDEX('Data Employee'!$B$2:$B$1000, MATCH(A11, 'Data Employee'!$A$2:$A$1000, 0)) -> Nadia Lestari | C11: =INDEX('Data Employee'!$G$2:$G$1000,MATCH(A11,'Data Employee'!$A$2:$A$1000,0)) -> Female | D11: {=IF(J11="","",_xlfn.IFS(DATEDIF(J11,TODAY(),"M")<12,"Contract 1",DATEDIF(J11,TODAY(),"M")<36,"Contract 2",DATEDIF(J11,TODAY(),"M")<60,"Contract 3",DATEDIF(J11,TODAY(),"M")<63,"Probation",TRUE,"Permanent"))} -> Permanent | E11: =IF(D11="Permanent","Permanent",IF(D11="Contract 1","12 Month",IF(D11="Contract 2","24 Month",IF(D11="Contract 3","60 Month",IF(D11="Probation","63 Month",""))))) -> Permanent | F11: =VLOOKUP(A11, 'Data Employee'!$A$2:$U$1000, 19, FALSE) -> Psychology | G11: =VLOOKUP(A11, 'Data Employee'!$A$2:$U$1000, 20, FALSE) -> Corporate Governance | H11: =INDEX('Data Employee'!$W$2:$W$1000, MATCH(A11, 'Data Employee'!$A$2:$A$1000, 0)) -> Chairman Commissioner | I11: =INDEX('Data Employee'!$V$2:$V$1000,MATCH(A11,'Data Employee'!$A$2:$A$1000,0)) -> Chairman Commissioner | J11: =INDEX('Data Employee'!$L$2:$L$1000, MATCH(A11, 'Data Employee'!$A$2:$A$1000, 0)) -> 38110 | K11: =IFERROR(IF(INDEX('Data Employee'!M:M,MATCH(A11,'Data Employee'!A:A,0))="","",INDEX('Data Employee'!M:M,MATCH(A11,'Data Employee'!A:A,0))),"") | L11: =IF(OR(K11="",K11<TODAY()),IF(K11="","","Expired"),DATEDIF(TODAY(),K11,"D")&" Days") | M11: =IF(OR(K11="", D11="Permanent", NOT(ISNUMBER(K11))), "Active", IF(K11<TODAY(), "Expired", IF(K11-TODAY()<=30, "Urgent Renewal", IF(K11-TODAY()<=60, "Review Needed", "Active")))) -> Active
A12: 201943658 | B12: =INDEX('Data Employee'!$B$2:$B$1000, MATCH(A12, 'Data Employee'!$A$2:$A$1000, 0)) -> Yusuf Pratama | C12: =INDEX('Data Employee'!$G$2:$G$1000,MATCH(A12,'Data Employee'!$A$2:$A$1000,0)) -> Male | D12: {=IF(J12="","",_xlfn.IFS(DATEDIF(J12,TODAY(),"M")<12,"Contract 1",DATEDIF(J12,TODAY(),"M")<36,"Contract 2",DATEDIF(J12,TODAY(),"M")<60,"Contract 3",DATEDIF(J12,TODAY(),"M")<63,"Probation",TRUE,"Permanent"))} -> Permanent | E12: =IF(D12="Permanent","Permanent",IF(D12="Contract 1","12 Month",IF(D12="Contract 2","24 Month",IF(D12="Contract 3","60 Month",IF(D12="Probation","63 Month",""))))) -> Permanent | F12: =VLOOKUP(A12, 'Data Employee'!$A$2:$U$1000, 19, FALSE) -> Law | G12: =VLOOKUP(A12, 'Data Employee'!$A$2:$U$1000, 20, FALSE) -> Corporate Governance | H12: =INDEX('Data Employee'!$W$2:$W$1000, MATCH(A12, 'Data Employee'!$A$2:$A$1000, 0)) -> Commissioner | I12: =INDEX('Data Employee'!$V$2:$V$1000,MATCH(A12,'Data Employee'!$A$2:$A$1000,0)) -> Commissioner | J12: =INDEX('Data Employee'!$L$2:$L$1000, MATCH(A12, 'Data Employee'!$A$2:$A$1000, 0)) -> 37084 | K12: =IFERROR(IF(INDEX('Data Employee'!M:M,MATCH(A12,'Data Employee'!A:A,0))="","",INDEX('Data Employee'!M:M,MATCH(A12,'Data Employee'!A:A,0))),"") | L12: =IF(OR(K12="",K12<TODAY()),IF(K12="","","Expired"),DATEDIF(TODAY(),K12,"D")&" Days") | M12: =IF(OR(K12="", D12="Permanent", NOT(ISNUMBER(K12))), "Active", IF(K12<TODAY(), "Expired", IF(K12-TODAY()<=30, "Urgent Renewal", IF(K12-TODAY()<=60, "Review Needed", "Active")))) -> Active
A13: 201441797 | B13: =INDEX('Data Employee'!$B$2:$B$1000, MATCH(A13, 'Data Employee'!$A$2:$A$1000, 0)) -> Dedi Permata | C13: =INDEX('Data Employee'!$G$2:$G$1000,MATCH(A13,'Data Employee'!$A$2:$A$1000,0)) -> Male | D13: {=IF(J13="","",_xlfn.IFS(DATEDIF(J13,TODAY(),"M")<12,"Contract 1",DATEDIF(J13,TODAY(),"M")<36,"Contract 2",DATEDIF(J13,TODAY(),"M")<60,"Contract 3",DATEDIF(J13,TODAY(),"M")<63,"Probation",TRUE,"Permanent"))} -> Permanent | E13: =IF(D13="Permanent","Permanent",IF(D13="Contract 1","12 Month",IF(D13="Contract 2","24 Month",IF(D13="Contract 3","60 Month",IF(D13="Probation","63 Month",""))))) -> Permanent | F13: =VLOOKUP(A13, 'Data Employee'!$A$2:$U$1000, 19, FALSE) -> Accounting | G13: =VLOOKUP(A13, 'Data Employee'!$A$2:$U$1000, 20, FALSE) -> Corporate Governance | H13: =INDEX('Data Employee'!$W$2:$W$1000, MATCH(A13, 'Data Employee'!$A$2:$A$1000, 0)) -> Commissioner | I13: =INDEX('Data Employee'!$V$2:$V$1000,MATCH(A13,'Data Employee'!$A$2:$A$1000,0)) -> Commissioner | J13: =INDEX('Data Employee'!$L$2:$L$1000, MATCH(A13, 'Data Employee'!$A$2:$A$1000, 0)) -> 37414 | K13: =IFERROR(IF(INDEX('Data Employee'!M:M,MATCH(A13,'Data Employee'!A:A,0))="","",INDEX('Data Employee'!M:M,MATCH(A13,'Data Employee'!A:A,0))),"") | L13: =IF(OR(K13="",K13<TODAY()),IF(K13="","","Expired"),DATEDIF(TODAY(),K13,"D")&" Days") | M13: =IF(OR(K13="", D13="Permanent", NOT(ISNUMBER(K13))), "Active", IF(K13<TODAY(), "Expired", IF(K13-TODAY()<=30, "Urgent Renewal", IF(K13-TODAY()<=60, "Review Needed", "Active")))) -> Active
... A307: 202545996 | B307: =INDEX('Data Employee'!$B$2:$B$1000, MATCH(A307, 'Data Employee'!$A$2:$A$1000, 0)) -> Dwi Kusnandar | C307: =INDEX('Data Employee'!$G$2:$G$1000,MATCH(A307,'Data Employee'!$A$2:$A$1000,0)) -> Male | D307: {=IF(J307="","",_xlfn.IFS(DATEDIF(J307,TODAY(),"M")<12,"Contract 1",DATEDIF(J307,TODAY(),"M")<36,"Contract 2",DATEDIF(J307,TODAY(),"M")<60,"Contract 3",DATEDIF(J307,TODAY(),"M")<63,"Probation",TRUE,"Permanent"))} -> Contract 1 | E307: =IF(D307="Permanent","Permanent",IF(D307="Contract 1","12 Month",IF(D307="Contract 2","24 Month",IF(D307="Contract 3","60 Month",IF(D307="Probation","63 Month",""))))) -> 12 Month | F307: =VLOOKUP(A307, 'Data Employee'!$A$2:$U$1000, 19, FALSE) -> Automotive Engineering | G307: =VLOOKUP(A307, 'Data Employee'!$A$2:$U$1000, 20, FALSE) -> Supply Chain Management | H307: =INDEX('Data Employee'!$W$2:$W$1000, MATCH(A307, 'Data Employee'!$A$2:$A$1000, 0)) -> Data Entry Intern | I307: =INDEX('Data Employee'!$V$2:$V$1000,MATCH(A307,'Data Employee'!$A$2:$A$1000,0)) -> Internship | J307: =INDEX('Data Employee'!$L$2:$L$1000, MATCH(A307, 'Data Employee'!$A$2:$A$1000, 0)) -> 45996 | K307: =IFERROR(IF(INDEX('Data Employee'!M:M,MATCH(A307,'Data Employee'!A:A,0))="","",INDEX('Data Employee'!M:M,MATCH(A307,'Data Employee'!A:A,0))),"") -> 46361 | L307: =IF(OR(K307="",K307<TODAY()),IF(K307="","","Expired"),DATEDIF(TODAY(),K307,"D")&" Days") -> 125 Days | M307: =IF(OR(K307="", D307="Permanent", NOT(ISNUMBER(K307))), "Active", IF(K307<TODAY(), "Expired", IF(K307-TODAY()<=30, "Urgent Renewal", IF(K307-TODAY()<=60, "Review Needed", "Active")))) -> Active

Sheet Data Employee
A1: Employee Number | B1: Full Name | C1: National ID Number (NIK) | D1: Family Card Number (KK) | E1: Place of Birth | F1: Date of Birth | G1: Gender | H1: Marital Status | I1: Dependent count | J1: Religion | K1: Blood Type | L1: Join Date | M1: End Date | N1: Exit Date | O1: Reason Saparation | P1: Employee Status | Q1: Employment Status | R1: Education | S1: Major | T1: Divison | U1: Departemen | V1: Job Level | W1: Job Title | X1: Grade | Y1: PTKP | Z1: Tax IDE (NPWP) | AA1: BPJS KPJ | AB1: BPJS JKN | AC1: Bank Name | AD1: Bank Acount | AE1: Mobile Phone | AF1: Email | AG1: Current Address
A2: 201743091 | B2: Dewi Pratama | C2: 3673261338071485 | D2: 4271920405157968 | E2: Padang | F2: 35084 | G2: Female | H2: Married | I2: =MIN(COUNTIFS('Data Family'!A:A,A2,'Data Family'!F:F,"Child")+COUNTIFS('Data Family'!A:A,A2,'Data Family'!F:F,"<>Child",'Data Family'!J:J,"Housewife")+COUNTIFS('Data Family'!A:A,A2,'Data Family'!F:F,"<>Child",'Data Family'!J:J,"Unemployment"),3) -> 0 | J2: Islam | K2: B | L2: 43091 | O2: =IF(AND(M2<>"", M2<=TODAY(), N2=""), "End of Contract", "") | P2: =IF(OR(N2<>"", AND(M2<>"",M2<=TODAY())),"Non-Active","Active") -> Active | Q2: =IF(M2="","PKWTT",IF(DATEDIF(L2,M2,"M")>63,"PKWTT",IF(DATEDIF(L2,M2,"M")>60,"PKWT",IF(DATEDIF(L2,M2,"M")>36,"PKWT",IF(DATEDIF(L2,M2,"M")>12, "PKWT","PKWT"))))) -> PKWTT | R2: Bachelor's Degree (S1) | S2: Accounting | T2: Management | U2: Accounting | V2: Officer / Executive | W2: Accounting Officer | X2: =_xlfn.XLOOKUP(V2,Reference!$O:$O,Reference!$N:$N,"Tidak Ketemu") -> G10 | Y2: =IF(AND(G2="Female",H2="Married"),"TK/0",IF(H2="Married","K/"&I2,"TK/"&I2)) -> TK/0 | Z2: 709598720199151 | AA2: 82725055991 | AB2: 7530534521305 | AC2: BANK BCA | AD2: 8222713255 | AE2: 087436886061 | AF2: dewi.pratama@dumibumi.co.id | AG2: Depok, Indonesia
A3: 201843228 | B3: Aulia Kurniawan | C3: 6583433931378082 | D3: 5074515261456100 | E3: Padang | F3: 35687 | G3: Female | H3: Married | I3: =MIN(COUNTIFS('Data Family'!A:A,A3,'Data Family'!F:F,"Child")+COUNTIFS('Data Family'!A:A,A3,'Data Family'!F:F,"<>Child",'Data Family'!J:J,"Housewife")+COUNTIFS('Data Family'!A:A,A3,'Data Family'!F:F,"<>Child",'Data Family'!J:J,"Unemployment"),3) -> 0 | J3: Islam | K3: A | L3: 43228 | O3: =IF(AND(M3<>"", M3<=TODAY(), N3=""), "End of Contract", "") | P3: =IF(OR(N3<>"", AND(M3<>"",M3<=TODAY())),"Non-Active","Active") -> Active | Q3: =IF(M3="","PKWTT",IF(DATEDIF(L3,M3,"M")>63,"PKWTT",IF(DATEDIF(L3,M3,"M")>60,"PKWT",IF(DATEDIF(L3,M3,"M")>36,"PKWT",IF(DATEDIF(L3,M3,"M")>12, "PKWT","PKWT"))))) -> PKWTT | R3: Bachelor's Degree (S1) | S3: Accounting | T3: Management | U3: Accounting | V3: Officer / Executive | W3: Accounting Officer | X3: =_xlfn.XLOOKUP(V3,Reference!$O:$O,Reference!$N:$N,"Tidak Ketemu") -> G10 | Y3: =IF(AND(G3="Female",H3="Married"),"TK/0",IF(H3="Married","K/"&I3,"TK/"&I3)) -> TK/0 | Z3: 697817412081533 | AA3: 02808925599 | AB3: 2285754017046 | AC3: BANK BCA | AD3: 2075046802 | AE3: 089998014789 | AF3: aulia.kurniawan@dumibumi.co.id | AG3: Depok, Indonesia
A4: 202043936 | B4: Putri Ramadhan | C4: 1641203662345718 | D4: 4630131291841621 | E4: Banjarbaru | F4: 32901 | G4: Female | H4: Married | I4: =MIN(COUNTIFS('Data Family'!A:A,A4,'Data Family'!F:F,"Child")+COUNTIFS('Data Family'!A:A,A4,'Data Family'!F:F,"<>Child",'Data Family'!J:J,"Housewife")+COUNTIFS('Data Family'!A:A,A4,'Data Family'!F:F,"<>Child",'Data Family'!J:J,"Unemployment"),3) -> 0 | J4: Islam | K4: A | L4: 45031 | M4: 46858 | O4: =IF(AND(M4<>"", M4<=TODAY(), N4=""), "End of Contract", "") | P4: =IF(OR(N4<>"", AND(M4<>"",M4<=TODAY())),"Non-Active","Active") -> Active | Q4: =IF(M4="","PKWTT",IF(DATEDIF(L4,M4,"M")>63,"PKWTT",IF(DATEDIF(L4,M4,"M")>60,"PKWT",IF(DATEDIF(L4,M4,"M")>36,"PKWT",IF(DATEDIF(L4,M4,"M")>12, "PKWT","PKWT"))))) -> PKWT | R4: Bachelor's Degree (S1) | S4: Accounting | T4: Management | U4: Accounting | V4: Staff | W4: Accounting Staff | X4: =_xlfn.XLOOKUP(V4,Reference!$O:$O,Reference!$N:$N,"Tidak Ketemu") -> G11 | Y4: =IF(AND(G4="Female",H4="Married"),"TK/0",IF(H4="Married","K/"&I4,"TK/"&I4)) -> TK/0 | Z4: 155058597700709 | AA4: 11885951137 | AB4: 2735238535208 | AC4: BANK BCA | AD4: 1619300215 | AE4: 085093968164 | AF4: putri.ramadhan@dumibumi.co.id | AG4: Bekasi, Indonesia
A5: 201743026 | B5: Indah Wijaya | C5: 3103831033928140 | D5: 5183770246714878 | E5: Padang | F5: 35653 | G5: Female | H5: Widowed | I5: =MIN(COUNTIFS('Data Family'!A:A,A5,'Data Family'!F:F,"Child")+COUNTIFS('Data Family'!A:A,A5,'Data Family'!F:F,"<>Child",'Data Family'!J:J,"Housewife")+COUNTIFS('Data Family'!A:A,A5,'Data Family'!F:F,"<>Child",'Data Family'!J:J,"Unemployment"),3) -> 1 | J5: Islam | K5: B | L5: 45583 | M5: 47409 | O5: =IF(AND(M5<>"", M5<=TODAY(), N5=""), "End of Contract", "") | P5: =IF(OR(N5<>"", AND(M5<>"",M5<=TODAY())),"Non-Active","Active") -> Active | Q5: =IF(M5="","PKWTT",IF(DATEDIF(L5,M5,"M")>63,"PKWTT",IF(DATEDIF(L5,M5,"M")>60,"PKWT",IF(DATEDIF(L5,M5,"M")>36,"PKWT",IF(DATEDIF(L5,M5,"M")>12, "PKWT","PKWT"))))) -> PKWT | R5: Bachelor's Degree (S1) | S5: Economics | T5: Management | U5: Accounting | V5: Staff | W5: Accounting Staff | X5: =_xlfn.XLOOKUP(V5,Reference!$O:$O,Reference!$N:$N,"Tidak Ketemu") -> G11 | Y5: =IF(AND(G5="Female",H5="Married"),"TK/0",IF(H5="Married","K/"&I5,"TK/"&I5)) -> TK/1 | Z5: 222635371015359 | AA5: 55677325613 | AB5: 5210410376198 | AC5: BANK BCA | AD5: 3973522993 | AE5: 088482832207 | AF5: indah.wijaya@dumibumi.co.id | AG5: Depok, Indonesia
A6: 201642668 | B6: Yulia Kurniawan | C6: 9357104470892611 | D6: 5396268764900697 | E6: Pasuruan | F6: 34390 | G6: Female | H6: Widowed | I6: =MIN(COUNTIFS('Data Family'!A:A,A6,'Data Family'!F:F,"Child")+COUNTIFS('Data Family'!A:A,A6,'Data Family'!F:F,"<>Child",'Data Family'!J:J,"Housewife")+COUNTIFS('Data Family'!A:A,A6,'Data Family'!F:F,"<>Child",'Data Family'!J:J,"Unemployment"),3) -> 2 | J6: Islam | K6: AB | L6: 44494 | M6: 46412 | O6: =IF(AND(M6<>"", M6<=TODAY(), N6=""), "End of Contract", "") | P6: =IF(OR(N6<>"", AND(M6<>"",M6<=TODAY())),"Non-Active","Active") -> Active | Q6: =IF(M6="","PKWTT",IF(DATEDIF(L6,M6,"M")>63,"PKWTT",IF(DATEDIF(L6,M6,"M")>60,"PKWT",IF(DATEDIF(L6,M6,"M")>36,"PKWT",IF(DATEDIF(L6,M6,"M")>12, "PKWT","PKWT"))))) -> PKWT | R6: Bachelor's Degree (S1) | S6: Business Administration | T6: Management | U6: Accounting | V6: Administrator | W6: Accounting Administration Staff | X6: =_xlfn.XLOOKUP(V6,Reference!$O:$O,Reference!$N:$N,"Tidak Ketemu") -> G12 | Y6: =IF(AND(G6="Female",H6="Married"),"TK/0",IF(H6="Married","K/"&I6,"TK/"&I6)) -> TK/2 | Z6: 828882004717425 | AA6: 55597668759 | AB6: 8721093658871 | AC6: BANK BCA | AD6: 5420497304 | AE6: 087695039746 | AF6: aulia.kurniawan@dumibumi.co.id | AG6: Subang, Indonesia
A7: 201843210 | B7: Rudi Saputra | C7: 2569196375513447 | D7: 5523131890314821 | E7: Bontang | F7: 32679 | G7: Male | H7: Married | I7: =MIN(COUNTIFS('Data Family'!A:A,A7,'Data Family'!F:F,"Child")+COUNTIFS('Data Family'!A:A,A7,'Data Family'!F:F,"<>Child",'Data Family'!J:J,"Housewife")+COUNTIFS('Data Family'!A:A,A7,'Data Family'!F:F,"<>Child",'Data Family'!J:J,"Unemployment"),3) -> 0 | J7: Islam | K7: AB | L7: 43210 | O7: =IF(AND(M7<>"", M7<=TODAY(), N7=""), "End of Contract", "") | P7: =IF(OR(N7<>"", AND(M7<>"",M7<=TODAY())),"Non-Active","Active") -> Active | Q7: =IF(M7="","PKWTT",IF(DATEDIF(L7,M7,"M")>63,"PKWTT",IF(DATEDIF(L7,M7,"M")>60,"PKWT",IF(DATEDIF(L7,M7,"M")>36,"PKWT",IF(DATEDIF(L7,M7,"M")>12, "PKWT","PKWT"))))) -> PKWTT | R7: Master's Degree (S2) | S7: Accounting | T7: Management | U7: Accounting | V7: Supervisor | W7: Accounting Supervisor | X7: =_xlfn.XLOOKUP(V7,Reference!$O:$O,Reference!$N:$N,"Tidak Ketemu") -> G07 | Y7: =IF(AND(G7="Female",H7="Married"),"TK/0",IF(H7="Married","K/"&I7,"TK/"&I7)) -> K/0 | Z7: 428422055744441 | AA7: 20032461858 | AB7: 6902535603224 | AC7: BANK BCA | AD7: 3288481171 | AE7: 080186359431 | AF7: rudi.saputra@dumibumi.co.id | AG7: Bekasi, Indonesia
A8: 202043917 | B8: Nadia Wijaya | C8: 0320996696887233 | D8: 8975850746827978 | E8: Bondowoso | F8: 32615 | G8: Female | H8: Married | I8: =MIN(COUNTIFS('Data Family'!A:A,A8,'Data Family'!F:F,"Child")+COUNTIFS('Data Family'!A:A,A8,'Data Family'!F:F,"<>Child",'Data Family'!J:J,"Housewife")+COUNTIFS('Data Family'!A:A,A8,'Data Family'!F:F,"<>Child",'Data Family'!J:J,"Unemployment"),3) -> 0 | J8: Islam | K8: AB | L8: 43186 | O8: =IF(AND(M8<>"", M8<=TODAY(), N8=""), "End of Contract", "") | P8: =IF(OR(N8<>"", AND(M8<>"",M8<=TODAY())),"Non-Active","Active") -> Active | Q8: =IF(M8="","PKWTT",IF(DATEDIF(L8,M8,"M")>63,"PKWTT",IF(DATEDIF(L8,M8,"M")>60,"PKWT",IF(DATEDIF(L8,M8,"M")>36,"PKWT",IF(DATEDIF(L8,M8,"M")>12, "PKWT","PKWT"))))) -> PKWTT | R8: Bachelor's Degree (S1) | S8: Accounting | T8: Corporate Governance | U8: Audit Committee | V8: Staff | W8: Audit Committee Staff | X8: =_xlfn.XLOOKUP(V8,Reference!$O:$O,Reference!$N:$N,"Tidak Ketemu") -> G11 | Y8: =IF(AND(G8="Female",H8="Married"),"TK/0",IF(H8="Married","K/"&I8,"TK/"&I8)) -> TK/0 | Z8: 611782068952825 | AA8: 32355111769 | AB8: 3580119418707 | AC8: BANK BCA | AD8: 6095340079 | AE8: 086097085665 | AF8: nadia.wijaya@dumibumi.co.id | AG8: Depok, Indonesia
A9: 201642597 | B9: Dedi Wijaya | C9: 9179297091629184 | D9: 1009783596581448 | E9: Jakarta | F9: 28543 | G9: Male | H9: Married | I9: =MIN(COUNTIFS('Data Family'!A:A,A9,'Data Family'!F:F,"Child")+COUNTIFS('Data Family'!A:A,A9,'Data Family'!F:F,"<>Child",'Data Family'!J:J,"Housewife")+COUNTIFS('Data Family'!A:A,A9,'Data Family'!F:F,"<>Child",'Data Family'!J:J,"Unemployment"),3) -> 2 | J9: Catholicism | K9: A | L9: 42597 | O9: =IF(AND(M9<>"", M9<=TODAY(), N9=""), "End of Contract", "") | P9: =IF(OR(N9<>"", AND(M9<>"",M9<=TODAY())),"Non-Active","Active") -> Active | Q9: =IF(M9="","PKWTT",IF(DATEDIF(L9,M9,"M")>63,"PKWTT",IF(DATEDIF(L9,M9,"M")>60,"PKWT",IF(DATEDIF(L9,M9,"M")>36,"PKWT",IF(DATEDIF(L9,M9,"M")>12, "PKWT","PKWT"))))) -> PKWTT | R9: Doctoral Degree (S3) | S9: Accounting | T9: Corporate Governance | U9: Audit Committee | V9: Manager | W9: Audit Committee Manager | X9: =_xlfn.XLOOKUP(V9,Reference!$O:$O,Reference!$N:$N,"Tidak Ketemu") -> G06 | Y9: =IF(AND(G9="Female",H9="Married"),"TK/0",IF(H9="Married","K/"&I9,"TK/"&I9)) -> K/2 | Z9: 949524386002951 | AA9: 38036856604 | AB9: 5675077907837 | AC9: BANK BCA | AD9: 3273225386 | AE9: 080222778568 | AF9: dedi.wijaya@dumibumi.co.id | AG9: Tangerang, Indonesia
A10: 202043908 | B10: Andi Ramadhan | C10: 9160452801959615 | D10: 1981732621458966 | E10: Blitar | F10: 33124 | G10: Male | H10: Married | I10: =MIN(COUNTIFS('Data Family'!A:A,A10,'Data Family'!F:F,"Child")+COUNTIFS('Data Family'!A:A,A10,'Data Family'!F:F,"<>Child",'Data Family'!J:J,"Housewife")+COUNTIFS('Data Family'!A:A,A10,'Data Family'!F:F,"<>Child",'Data Family'!J:J,"Unemployment"),3) -> 1 | J10: Islam | K10: B | L10: 43542 | O10: =IF(AND(M10<>"", M10<=TODAY(), N10=""), "End of Contract", "") | P10: =IF(OR(N10<>"", AND(M10<>"",M10<=TODAY())),"Non-Active","Active") -> Active | Q10: =IF(M10="","PKWTT",IF(DATEDIF(L10,M10,"M")>63,"PKWTT",IF(DATEDIF(L10,M10,"M")>60,"PKWT",IF(DATEDIF(L10,M10,"M")>36,"PKWT",IF(DATEDIF(L10,M10,"M")>12, "PKWT","PKWT"))))) -> PKWTT | R10: Master's Degree (S2) | S10: Management | T10: Corporate Governance | U10: Audit Committee | V10: Staff | W10: Audit Committee Staff | X10: =_xlfn.XLOOKUP(V10,Reference!$O:$O,Reference!$N:$N,"Tidak Ketemu") -> G11 | Y10: =IF(AND(G10="Female",H10="Married"),"TK/0",IF(H10="Married","K/"&I10,"TK/"&I10)) -> K/1 | Z10: 688059400228650 | AA10: 81699686056 | AB10: 7271450042870 | AC10: BANK BCA | AD10: 7280495357 | AE10: 083040551531 | AF10: andi.ramadhan@dumibumi.co.id | AG10: Bandung, Indonesia
A11: 202043954 | B11: Nadia Lestari | C11: 7134371159410775 | D11: 7257837349082723 | E11: Bandung | F11: 28118 | G11: Female | H11: Married | I11: =MIN(COUNTIFS('Data Family'!A:A,A11,'Data Family'!F:F,"Child")+COUNTIFS('Data Family'!A:A,A11,'Data Family'!F:F,"<>Child",'Data Family'!J:J,"Housewife")+COUNTIFS('Data Family'!A:A,A11,'Data Family'!F:F,"<>Child",'Data Family'!J:J,"Unemployment"),3) -> 0 | J11: Islam | K11: AB | L11: 38110 | O11: =IF(AND(M11<>"", M11<=TODAY(), N11=""), "End of Contract", "") | P11: =IF(OR(N11<>"", AND(M11<>"",M11<=TODAY())),"Non-Active","Active") -> Active | Q11: =IF(M11="","PKWTT",IF(DATEDIF(L11,M11,"M")>63,"PKWTT",IF(DATEDIF(L11,M11,"M")>60,"PKWT",IF(DATEDIF(L11,M11,"M")>36,"PKWT",IF(DATEDIF(L11,M11,"M")>12, "PKWT","PKWT"))))) -> PKWTT | R11: Master's Degree (S2) | S11: Psychology | T11: Corporate Governance | U11: Board of Commissioners | V11: Chairman Commissioner | W11: Chairman Commissioner | X11: =_xlfn.XLOOKUP(V11,Reference!$O:$O,Reference!$N:$N,"Tidak Ketemu") -> G02 | Y11: =IF(AND(G11="Female",H11="Married"),"TK/0",IF(H11="Married","K/"&I11,"TK/"&I11)) -> TK/0 | Z11: 695365629362010 | AA11: 45394320070 | AB11: 0749322108059 | AC11: BANK BCA | AD11: 1582000195 | AE11: 089416729767 | AF11: nadia.pratama@dumibumi.co.id | AG11: Jakarta, Indonesia
A12: 201943658 | B12: Yusuf Pratama | C12: 5291622520708200 | D12: 2473439042449944 | E12: Pontianak | F12: 28095 | G12: Male | H12: Married | I12: =MIN(COUNTIFS('Data Family'!A:A,A12,'Data Family'!F:F,"Child")+COUNTIFS('Data Family'!A:A,A12,'Data Family'!F:F,"<>Child",'Data Family'!J:J,"Housewife")+COUNTIFS('Data Family'!A:A,A12,'Data Family'!F:F,"<>Child",'Data Family'!J:J,"Unemployment"),3) -> 1 | J12: Islam | K12: O | L12: 37084 | O12: =IF(AND(M12<>"", M12<=TODAY(), N12=""), "End of Contract", "") | P12: =IF(OR(N12<>"", AND(M12<>"",M12<=TODAY())),"Non-Active","Active") -> Active | Q12: =IF(M12="","PKWTT",IF(DATEDIF(L12,M12,"M")>63,"PKWTT",IF(DATEDIF(L12,M12,"M")>60,"PKWT",IF(DATEDIF(L12,M12,"M")>36,"PKWT",IF(DATEDIF(L12,M12,"M")>12, "PKWT","PKWT"))))) -> PKWTT | R12: Master's Degree (S2) | S12: Law | T12: Corporate Governance | U12: Board of Commissioners | V12: Commissioner | W12: Commissioner | X12: =_xlfn.XLOOKUP(V12,Reference!$O:$O,Reference!$N:$N,"Tidak Ketemu") -> G03 | Y12: =IF(AND(G12="Female",H12="Married"),"TK/0",IF(H12="Married","K/"&I12,"TK/"&I12)) -> K/1 | Z12: 544369555345556 | AA12: 75285941818 | AB12: 8437463760121 | AC12: BANK BCA | AD12: 4014998198 | AE12: 080931955459 | AF12: yusuf.pratama@dumibumi.co.id | AG12: Tangerang, Indonesia
A13: 201441797 | B13: Dedi Permata | C13: 1693422781672131 | D13: 6297683498710681 | E13: Banjarmasin | F13: 26323 | G13: Male | H13: Married | I13: =MIN(COUNTIFS('Data Family'!A:A,A13,'Data Family'!F:F,"Child")+COUNTIFS('Data Family'!A:A,A13,'Data Family'!F:F,"<>Child",'Data Family'!J:J,"Housewife")+COUNTIFS('Data Family'!A:A,A13,'Data Family'!F:F,"<>Child",'Data Family'!J:J,"Unemployment"),3) -> 2 | J13: Hinduism | K13: A | L13: 37414 | O13: =IF(AND(M13<>"", M13<=TODAY(), N13=""), "End of Contract", "") | P13: =IF(OR(N13<>"", AND(M13<>"",M13<=TODAY())),"Non-Active","Active") -> Active | Q13: =IF(M13="","PKWTT",IF(DATEDIF(L13,M13,"M")>63,"PKWTT",IF(DATEDIF(L13,M13,"M")>60,"PKWT",IF(DATEDIF(L13,M13,"M")>36,"PKWT",IF(DATEDIF(L13,M13,"M")>12, "PKWT","PKWT"))))) -> PKWTT | R13: Doctoral Degree (S3) | S13: Accounting | T13: Corporate Governance | U13: Board of Commissioners | V13: Commissioner | W13: Commissioner | X13: =_xlfn.XLOOKUP(V13,Reference!$O:$O,Reference!$N:$N,"Tidak Ketemu") -> G03 | Y13: =IF(AND(G13="Female",H13="Married"),"TK/0",IF(H13="Married","K/"&I13,"TK/"&I13)) -> K/2 | Z13: 761373300266873 | AA13: 71401237162 | AB13: 1682486458067 | AC13: BANK BCA | AD13: 6054335163 | AE13: 081075935793 | AF13: dedi.permata@dumibumi.co.id | AG13: Bogor, Indonesia
A14: 202244911 | B14: Monica Putri Ayu | C14: 8868713042755589 | D14: 7700585616611204 | E14: Sukabumi | F14: 32692 | G14: Female | H14: Married | I14: =MIN(COUNTIFS('Data Family'!A:A,A14,'Data Family'!F:F,"Child")+COUNTIFS('Data Family'!A:A,A14,'Data Family'!F:F,"<>Child",'Data Family'!J:J,"Housewife")+COUNTIFS('Data Family'!A:A,A14,'Data Family'!F:F,"<>Child",'Data Family'!J:J,"Unemployment"),3) -> 0 | J14: Catholicism | K14: B | L14: 44911 | M14: 46737 | O14: =IF(AND(M14<>"", M14<=TODAY(), N14=""), "End of Contract", "") | P14: =IF(OR(N14<>"", AND(M14<>"",M14<=TODAY())),"Non-Active","Active") -> Active | Q14: =IF(M14="","PKWTT",IF(DATEDIF(L14,M14,"M")>63,"PKWTT",IF(DATEDIF(L14,M14,"M")>60,"PKWT",IF(DATEDIF(L14,M14,"M")>36,"PKWT",IF(DATEDIF(L14,M14,"M")>12, "PKWT","PKWT"))))) -> PKWT | R14: Master's Degree (S2) | S14: Business Administration | T14: Corporate Governance | U14: Corporate Secretary | V14: Officer / Executive | W14: Corporate Secretary | X14: =_xlfn.XLOOKUP(V14,Reference!$O:$O,Reference!$N:$N,"Tidak Ketemu") -> G10 | Y14: =IF(AND(G14="Female",H14="Married"),"TK/0",IF(H14="Married","K/"&I14,"TK/"&I14)) -> TK/0 | Z14: 495344004861489 | AA14: 73880099287 | AB14: 8313499899159 | AC14: BANK BCA | AD14: 8781658784 | AE14: 088688061334 | AF14: lina.wijaya@dumibumi.co.id | AG14: Tangerang, Indonesia
A15: 201542050 | B15: Fajar Hidayat | C15: 6898050111354868 | D15: 0069685671645996 | E15: Karawang | F15: 33170 | G15: Male | H15: Married | I15: =MIN(COUNTIFS('Data Family'!A:A,A15,'Data Family'!F:F,"Child")+COUNTIFS('Data Family'!A:A,A15,'Data Family'!F:F,"<>Child",'Data Family'!J:J,"Housewife")+COUNTIFS('Data Family'!A:A,A15,'Data Family'!F:F,"<>Child",'Data Family'!J:J,"Unemployment"),3) -> 0 | J15: Protestantism | K15: A | L15: 42050 | O15: =IF(AND(M15<>"", M15<=TODAY(), N15=""), "End of Contract", "") | P15: =IF(OR(N15<>"", AND(M15<>"",M15<=TODAY())),"Non-Active","Active") -> Active | Q15: =IF(M15="","PKWTT",IF(DATEDIF(L15,M15,"M")>63,"PKWTT",IF(DATEDIF(L15,M15,"M")>60,"PKWT",IF(DATEDIF(L15,M15,"M")>36,"PKWT",IF(DATEDIF(L15,M15,"M")>12, "PKWT","PKWT"))))) -> PKWTT | R15: Bachelor's Degree (S1) | S15: Economics | T15: Management | U15: Finance | V15: Officer / Executive | W15: Finance Officer | X15: =_xlfn.XLOOKUP(V15,Reference!$O:$O,Reference!$N:$N,"Tidak Ketemu") -> G10 | Y15: =IF(AND(G15="Female",H15="Married"),"TK/0",IF(H15="Married","K/"&I15,"TK/"&I15)) -> K/0 | Z15: 898971049654288 | AA15: 94680223451 | AB15: 5094269625937 | AC15: BANK BCA | AD15: 2879944152 | AE15: 082061927319 | AF15: fajar.hidayat@dumibumi.co.id | AG15: Bandung, Indonesia
A16: 202144304 | B16: Aulia Wijaya | C16: 5982503451061249 | D16: 9725075839427925 | E16: Banjarbaru | F16: 32735 | G16: Female | H16: Married | I16: =MIN(COUNTIFS('Data Family'!A:A,A16,'Data Family'!F:F,"Child")+COUNTIFS('Data Family'!A:A,A16,'Data Family'!F:F,"<>Child",'Data Family'!J:J,"Housewife")+COUNTIFS('Data Family'!A:A,A16,'Data Family'!F:F,"<>Child",'Data Family'!J:J,"Unemployment"),3) -> 1 | J16: Protestantism | K16: AB | L16: 45765 | M16: 46495 | O16: =IF(AND(M16<>"", M16<=TODAY(), N16=""), "End of Contract", "") | P16: =IF(OR(N16<>"", AND(M16<>"",M16<=TODAY())),"Non-Active","Active") -> Active | Q16: =IF(M16="","PKWTT",IF(DATEDIF(L16,M16,"M")>63,"PKWTT",IF(DATEDIF(L16,M16,"M")>60,"PKWT",IF(DATEDIF(L16,M16,"M")>36,"PKWT",IF(DATEDIF(L16,M16,"M")>12, "PKWT","PKWT"))))) -> PKWT | R16: Bachelor's Degree (S1) | S16: Economics | T16: Management | U16: Finance | V16: Officer / Executive | W16: Finance Officer | X16: =_xlfn.XLOOKUP(V16,Reference!$O:$O,Reference!$N:$N,"Tidak Ketemu") -> G10 | Y16: =IF(AND(G16="Female",H16="Married"),"TK/0",IF(H16="Married","K/"&I16,"TK/"&I16)) -> TK/0 | Z16: 366164511585083 | AA16: 52628474546 | AB16: 2472644929257 | AC16: BANK BCA | AD16: 0653257942 | AE16: 080397593061 | AF16: aulia.wijaya@dumibumi.co.id | AG16: Jakarta, Indonesia
A17: 202043907 | B17: Dewi Sari | C17: 7046351185862305 | D17: 9459454797742185 | E17: Samarinda | F17: 34844 | G17: Female | H17: Widowed | I17: =MIN(COUNTIFS('Data Family'!A:A,A17,'Data Family'!F:F,"Child")+COUNTIFS('Data Family'!A:A,A17,'Data Family'!F:F,"<>Child",'Data Family'!J:J,"Housewife")+COUNTIFS('Data Family'!A:A,A17,'Data Family'!F:F,"<>Child",'Data Family'!J:J,"Unemployment"),3) -> 2 | J17: Islam | K17: O | L17: 43907 | O17: =IF(AND(M17<>"", M17<=TODAY(), N17=""), "End of Contract", "") | P17: =IF(OR(N17<>"", AND(M17<>"",M17<=TODAY())),"Non-Active","Active") -> Active | Q17: =IF(M17="","PKWTT",IF(DATEDIF(L17,M17,"M")>63,"PKWTT",IF(DATEDIF(L17,M17,"M")>60,"PKWT",IF(DATEDIF(L17,M17,"M")>36,"PKWT",IF(DATEDIF(L17,M17,"M")>12, "PKWT","PKWT"))))) -> PKWTT | R17: Bachelor's Degree (S1) | S17: Accounting | T17: Management | U17: Finance | V17: Staff | W17: Finance Staff | X17: =_xlfn.XLOOKUP(V17,Reference!$O:$O,Reference!$N:$N,"Tidak Ketemu") -> G11 | Y17: =IF(AND(G17="Female",H17="Married"),"TK/0",IF(H17="Married","K/"&I17,"TK/"&I17)) -> TK/2 | Z17: 263396533418708 | AA17: 93397124597 | AB17: 3914679964832 | AC17: BANK BCA | AD17: 9298907969 | AE17: 087685367471 | AF17: dewi.sari@dumibumi.co.id | AG17: Depok, Indonesia
A18: 201742744 | B18: Nadia Santoso | C18: 6756449784102128 | D18: 0832902389588048 | E18: Pasuruan | F18: 35872 | G18: Female | H18: Married | I18: =MIN(COUNTIFS('Data Family'!A:A,A18,'Data Family'!F:F,"Child")+COUNTIFS('Data Family'!A:A,A18,'Data Family'!F:F,"<>Child",'Data Family'!J:J,"Housewife")+COUNTIFS('Data Family'!A:A,A18,'Data Family'!F:F,"<>Child",'Data Family'!J:J,"Unemployment"),3) -> 0 | J18: Islam | K18: O | L18: 46031 | M18: 46396 | O18: =IF(AND(M18<>"", M18<=TODAY(), N18=""), "End of Contract", "") | P18: =IF(OR(N18<>"", AND(M18<>"",M18<=TODAY())),"Non-Active","Active") -> Active | Q18: =IF(M18="","PKWTT",IF(DATEDIF(L18,M18,"M")>63,"PKWTT",IF(DATEDIF(L18,M18,"M")>60,"PKWT",IF(DATEDIF(L18,M18,"M")>36,"PKWT",IF(DATEDIF(L18,M18,"M")>12, "PKWT","PKWT"))))) -> PKWT | R18: Bachelor's Degree (S1) | S18: Communication | T18: Management | U18: Finance | V18: Administrator | W18: Finance Administration Staff | X18: =_xlfn.XLOOKUP(V18,Reference!$O:$O,Reference!$N:$N,"Tidak Ketemu") -> G12 | Y18: =IF(AND(G18="Female",H18="Married"),"TK/0",IF(H18="Married","K/"&I18,"TK/"&I18)) -> TK/0 | Z18: 439711887629562 | AA18: 85155573251 | AB18: 1472671998475 | AC18: BANK BCA | AD18: 4733934962 | AE18: 082766903492 | AF18: nadia.santoso@dumibumi.co.id | AG18: Bogor, Indonesia
A19: 202445629 | B19: Jajang Kusuma | C19: 3877001018943814 | D19: 2.2066493e+15 | E19: Pasuruan | F19: 31364 | G19: Male | H19: Married | I19: =MIN(COUNTIFS('Data Family'!A:A,A19,'Data Family'!F:F,"Child")+COUNTIFS('Data Family'!A:A,A19,'Data Family'!F:F,"<>Child",'Data Family'!J:J,"Housewife")+COUNTIFS('Data Family'!A:A,A19,'Data Family'!F:F,"<>Child",'Data Family'!J:J,"Unemployment"),3) -> 0 | J19: Catholicism | K19: B | L19: 42707 | O19: =IF(AND(M19<>"", M19<=TODAY(), N19=""), "End of Contract", "") | P19: =IF(OR(N19<>"", AND(M19<>"",M19<=TODAY())),"Non-Active","Active") -> Active | Q19: =IF(M19="","PKWTT",IF(DATEDIF(L19,M19,"M")>63,"PKWTT",IF(DATEDIF(L19,M19,"M")>60,"PKWT",IF(DATEDIF(L19,M19,"M")>36,"PKWT",IF(DATEDIF(L19,M19,"M")>12, "PKWT","PKWT"))))) -> PKWTT | R19: Master's Degree (S2) | S19: Accounting | T19: Management | U19: Finance | V19: Manager | W19: Finance Manager | X19: =_xlfn.XLOOKUP(V19,Reference!$O:$O,Reference!$N:$N,"Tidak Ketemu") -> G06 | Y19: =IF(AND(G19="Female",H19="Married"),"TK/0",IF(H19="Married","K/"&I19,"TK/"&I19)) -> K/0 | Z19: 143803499431951 | AA19: 06411236925 | AB19: 8723672671458 | AC19: BANK BCA | AD19: 4821837876 | AE19: 085964897453 | AF19: aulia.kusuma@dumibumi.co.id | AG19: Bandung, Indonesia
A20: 201743013 | B20: Bayu Santoso | C20: 9964177721912332 | D20: 2008506307534749 | E20: Karawang | F20: 28809 | G20: Male | H20: Married | I20: =MIN(COUNTIFS('Data Family'!A:A,A20,'Data Family'!F:F,"Child")+COUNTIFS('Data Family'!A:A,A20,'Data Family'!F:F,"<>Child",'Data Family'!J:J,"Housewife")+COUNTIFS('Data Family'!A:A,A20,'Data Family'!F:F,"<>Child",'Data Family'!J:J,"Unemployment"),3) -> 2 | J20: Catholicism | K20: B | L20: 43013 | O20: =IF(AND(M20<>"", M20<=TODAY(), N20=""), "End of Contract", "") | P20: =IF(OR(N20<>"", AND(M20<>"",M20<=TODAY())),"Non-Active","Active") -> Active | Q20: =IF(M20="","PKWTT",IF(DATEDIF(L20,M20,"M")>63,"PKWTT",IF(DATEDIF(L20,M20,"M")>60,"PKWT",IF(DATEDIF(L20,M20,"M")>36,"PKWT",IF(DATEDIF(L20,M20,"M")>12, "PKWT","PKWT"))))) -> PKWTT | R20: Doctoral Degree (S3) | S20: Accounting | T20: Management | U20: Finance | V20: General Manager | W20: General Manager | X20: =_xlfn.XLOOKUP(V20,Reference!$O:$O,Reference!$N:$N,"Tidak Ketemu") -> G05 | Y20: =IF(AND(G20="Female",H20="Married"),"TK/0",IF(H20="Married","K/"&I20,"TK/"&I20)) -> K/2 | Z20: 199317952841093 | AA20: 44115713928 | AB20: 8483334572963 | AC20: BANK BCA | AD20: 0975713985 | AE20: 080595210902 | AF20: bayu.santoso@dumibumi.co.id | AG20: Bandung, Indonesia
A21: 202244751 | B21: Fajar Saputra | C21: 4752176185887151 | D21: 6232132117560140 | E21: Jakarta | F21: 31683 | G21: Male | H21: Married | I21: =MIN(COUNTIFS('Data Family'!A:A,A21,'Data Family'!F:F,"Child")+COUNTIFS('Data Family'!A:A,A21,'Data Family'!F:F,"<>Child",'Data Family'!J:J,"Housewife")+COUNTIFS('Data Family'!A:A,A21,'Data Family'!F:F,"<>Child",'Data Family'!J:J,"Unemployment"),3) -> 0 | J21: Islam | K21: A | L21: 42194 | O21: =IF(AND(M21<>"", M21<=TODAY(), N21=""), "End of Contract", "") | P21: =IF(OR(N21<>"", AND(M21<>"",M21<=TODAY())),"Non-Active","Active") -> Active | Q21: =IF(M21="","PKWTT",IF(DATEDIF(L21,M21,"M")>63,"PKWTT",IF(DATEDIF(L21,M21,"M")>60,"PKWT",IF(DATEDIF(L21,M21,"M")>36,"PKWT",IF(DATEDIF(L21,M21,"M")>12, "PKWT","PKWT"))))) -> PKWTT | R21: Master's Degree (S2) | S21: Accounting | T21: Management | U21: Finance | V21: Supervisor | W21: Finance Supervisor | X21: =_xlfn.XLOOKUP(V21,Reference!$O:$O,Reference!$N:$N,"Tidak Ketemu") -> G07 | Y21: =IF(AND(G21="Female",H21="Married"),"TK/0",IF(H21="Married","K/"&I21,"TK/"&I21)) -> K/0 | Z21: 494080087700032 | AA21: 47670283666 | AB21: 1929086667506 | AC21: BANK BCA | AD21: 3785409084 | AE21: 080993139962 | AF21: fajar.saputra@dumibumi.co.id | AG21: Bandung, Indonesia
A22: 201943709 | B22: Farhan Arif Firmansyah | C22: 7224481878566736 | D22: 2794564114648111 | E22: Jakarta | F22: 32348 | G22: Male | H22: Married | I22: =MIN(COUNTIFS('Data Family'!A:A,A22,'Data Family'!F:F,"Child")+COUNTIFS('Data Family'!A:A,A22,'Data Family'!F:F,"<>Child",'Data Family'!J:J,"Housewife")+COUNTIFS('Data Family'!A:A,A22,'Data Family'!F:F,"<>Child",'Data Family'!J:J,"Unemployment"),3) -> 0 | J22: Islam | K22: A | L22: 42979 | O22: =IF(AND(M22<>"", M22<=TODAY(), N22=""), "End of Contract", "") | P22: =IF(OR(N22<>"", AND(M22<>"",M22<=TODAY())),"Non-Active","Active") -> Active | Q22: =IF(M22="","PKWTT",IF(DATEDIF(L22,M22,"M")>63,"PKWTT",IF(DATEDIF(L22,M22,"M")>60,"PKWT",IF(DATEDIF(L22,M22,"M")>36,"PKWT",IF(DATEDIF(L22,M22,"M")>12, "PKWT","PKWT"))))) -> PKWTT | R22: Master's Degree (S2) | S22: Law | T22: Human Resources | U22: Human Resources & General Affairs | V22: Manager | W22: Human Resources Manager | X22: =_xlfn.XLOOKUP(V22,Reference!$O:$O,Reference!$N:$N,"Tidak Ketemu") -> G06 | Y22: =IF(AND(G22="Female",H22="Married"),"TK/0",IF(H22="Married","K/"&I22,"TK/"&I22)) -> K/0 | Z22: 676791160188610 | AA22: 80544586070 | AB22: 5907762254884 | AC22: BANK BCA | AD22: 4105124328 | AE22: 086298054608 | AF22: farhan.sari@dumibumi.co.id | AG22: Tangerang, Indonesia
A23: 201743013 | B23: Rudi Nugroho | C23: 8497101319935159 | D23: 0197669065659725 | E23: Pontianak | F23: 32853 | G23: Male | H23: Married | I23: =MIN(COUNTIFS('Data Family'!A:A,A23,'Data Family'!F:F,"Child")+COUNTIFS('Data Family'!A:A,A23,'Data Family'!F:F,"<>Child",'Data Family'!J:J,"Housewife")+COUNTIFS('Data Family'!A:A,A23,'Data Family'!F:F,"<>Child",'Data Family'!J:J,"Unemployment"),3) -> 2 | J23: Islam | K23: A | L23: 43743 | O23: =IF(AND(M23<>"", M23<=TODAY(), N23=""), "End of Contract", "") | P23: =IF(OR(N23<>"", AND(M23<>"",M23<=TODAY())),"Non-Active","Active") -> Active | Q23: =IF(M23="","PKWTT",IF(DATEDIF(L23,M23,"M")>63,"PKWTT",IF(DATEDIF(L23,M23,"M")>60,"PKWT",IF(DATEDIF(L23,M23,"M")>36,"PKWT",IF(DATEDIF(L23,M23,"M")>12, "PKWT","PKWT"))))) -> PKWTT | R23: Master's Degree (S2) | S23: Psychology | T23: Human Resources | U23: Human Resources & General Affairs | V23: Supervisor | W23: HR Ops & GA Supervisor | X23: =_xlfn.XLOOKUP(V23,Reference!$O:$O,Reference!$N:$N,"Tidak Ketemu") -> G07 | Y23: =IF(AND(G23="Female",H23="Married"),"TK/0",IF(H23="Married","K/"&I23,"TK/"&I23)) -> K/2 | Z23: 358552492655382 | AA23: 57099509411 | AB23: 2661899472091 | AC23: BANK BCA | AD23: 6415986560 | AE23: 083952384227 | AF23: rudi.nugroho@dumibumi.co.id | AG23: Bandung, Indonesia
A24: 202044117 | B24: Reza Nurfadilah Restu | C24: 7290990647659812 | D24: 6598383403479966 | E24: Pontianak | F24: 33071 | G24: Male | H24: Married | I24: =MIN(COUNTIFS('Data Family'!A:A,A24,'Data Family'!F:F,"Child")+COUNTIFS('Data Family'!A:A,A24,'Data Family'!F:F,"<>Child",'Data Family'!J:J,"Housewife")+COUNTIFS('Data Family'!A:A,A24,'Data Family'!F:F,"<>Child",'Data Family'!J:J,"Unemployment"),3) -> 0 | J24: Islam | K24: O | L24: 43386 | O24: =IF(AND(M24<>"", M24<=TODAY(), N24=""), "End of Contract", "") | P24: =IF(OR(N24<>"", AND(M24<>"",M24<=TODAY())),"Non-Active","Active") -> Active | Q24: =IF(M24="","PKWTT",IF(DATEDIF(L24,M24,"M")>63,"PKWTT",IF(DATEDIF(L24,M24,"M")>60,"PKWT",IF(DATEDIF(L24,M24,"M")>36,"PKWT",IF(DATEDIF(L24,M24,"M")>12, "PKWT","PKWT"))))) -> PKWTT | R24: Master's Degree (S2) | S24: Psychology | T24: Human Resources | U24: Human Resources & General Affairs | V24: Officer / Executive | W24: Learning & Development Officer | X24: =_xlfn.XLOOKUP(V24,Reference!$O:$O,Reference!$N:$N,"Tidak Ketemu") -> G10 | Y24: =IF(AND(G24="Female",H24="Married"),"TK/0",IF(H24="Married","K/"&I24,"TK/"&I24)) -> K/0 | Z24: 924206916648484 | AA24: 72572281606 | AB24: 4689461181583 | AC24: BANK BCA | AD24: 5777535686 | AE24: 083007658580 | AF24: farhan.permata@dumibumi.co.id | AG24: Tangerang, Indonesia
A25: 202043987 | B25: Musdalifah | C25: 2329496771686555 | D25: 8037517371109425 | E25: Singkawang | F25: 33684 | G25: Female | H25: Married | I25: =MIN(COUNTIFS('Data Family'!A:A,A25,'Data Family'!F:F,"Child")+COUNTIFS('Data Family'!A:A,A25,'Data Family'!F:F,"<>Child",'Data Family'!J:J,"Housewife")+COUNTIFS('Data Family'!A:A,A25,'Data Family'!F:F,"<>Child",'Data Family'!J:J,"Unemployment"),3) -> 0 | J25: Islam | K25: AB | L25: 43987 | O25: =IF(AND(M25<>"", M25<=TODAY(), N25=""), "End of Contract", "") | P25: =IF(OR(N25<>"", AND(M25<>"",M25<=TODAY())),"Non-Active","Active") -> Active | Q25: =IF(M25="","PKWTT",IF(DATEDIF(L25,M25,"M")>63,"PKWTT",IF(DATEDIF(L25,M25,"M")>60,"PKWT",IF(DATEDIF(L25,M25,"M")>36,"PKWT",IF(DATEDIF(L25,M25,"M")>12, "PKWT","PKWT"))))) -> PKWTT | R25: Bachelor's Degree (S1) | S25: Psychology | T25: Human Resources | U25: Human Resources & General Affairs | V25: Officer / Executive | W25: HR Communications Officer | X25: =_xlfn.XLOOKUP(V25,Reference!$O:$O,Reference!$N:$N,"Tidak Ketemu") -> G10 | Y25: =IF(AND(G25="Female",H25="Married"),"TK/0",IF(H25="Married","K/"&I25,"TK/"&I25)) -> TK/0 | Z25: 937009148998113 | AA25: 72008129905 | AB25: 2326690143540 | AC25: BANK BCA | AD25: 9553316196 | AE25: 084516707178 | AF25: nadia.wijaya@dumibumi.co.id | AG25: Bogor, Indonesia
A26: 201943752 | B26: Rizky Permata | C26: 4901950672851294 | D26: 9749050973474001 | E26: Banjarmasin | F26: 34230 | G26: Male | H26: Married | I26: =MIN(COUNTIFS('Data Family'!A:A,A26,'Data Family'!F:F,"Child")+COUNTIFS('Data Family'!A:A,A26,'Data Family'!F:F,"<>Child",'Data Family'!J:J,"Housewife")+COUNTIFS('Data Family'!A:A,A26,'Data Family'!F:F,"<>Child",'Data Family'!J:J,"Unemployment"),3) -> 0 | J26: Islam | K26: B | L26: 43752 | O26: =IF(AND(M26<>"", M26<=TODAY(), N26=""), "End of Contract", "") | P26: =IF(OR(N26<>"", AND(M26<>"",M26<=TODAY())),"Non-Active","Active") -> Active | Q26: =IF(M26="","PKWTT",IF(DATEDIF(L26,M26,"M")>63,"PKWTT",IF(DATEDIF(L26,M26,"M")>60,"PKWT",IF(DATEDIF(L26,M26,"M")>36,"PKWT",IF(DATEDIF(L26,M26,"M")>12, "PKWT","PKWT"))))) -> PKWTT | R26: Bachelor's Degree (S1) | S26: Management | T26: Human Resources | U26: Human Resources & General Affairs | V26: Officer / Executive | W26: Payroll & Benefits Officer | X26: =_xlfn.XLOOKUP(V26,Reference!$O:$O,Reference!$N:$N,"Tidak Ketemu") -> G10 | Y26: =IF(AND(G26="Female",H26="Married"),"TK/0",IF(H26="Married","K/"&I26,"TK/"&I26)) -> K/0 | Z26: 063449011015272 | AA26: 33802505957 | AB26: 8905850993780 | AC26: BANK BCA | AD26: 6664172510 | AE26: 080774942620 | AF26: rizky.permata@dumibumi.co.id | AG26: Tangerang, Indonesia
A27: 202144365 | B27: Aulia Pratama | C27: 3061485360217420 | D27: 5592059614579362 | E27: Karawang | F27: 34595 | G27: Female | H27: Married | I27: =MIN(COUNTIFS('Data Family'!A:A,A27,'Data Family'!F:F,"Child")+COUNTIFS('Data Family'!A:A,A27,'Data Family'!F:F,"<>Child",'Data Family'!J:J,"Housewife")+COUNTIFS('Data Family'!A:A,A27,'Data Family'!F:F,"<>Child",'Data Family'!J:J,"Unemployment"),3) -> 2 | J27: Islam | K27: A | L27: 45887 | M27: 46617 | O27: =IF(AND(M27<>"", M27<=TODAY(), N27=""), "End of Contract", "") | P27: =IF(OR(N27<>"", AND(M27<>"",M27<=TODAY())),"Non-Active","Active") -> Active | Q27: =IF(M27="","PKWTT",IF(DATEDIF(L27,M27,"M")>63,"PKWTT",IF(DATEDIF(L27,M27,"M")>60,"PKWT",IF(DATEDIF(L27,M27,"M")>36,"PKWT",IF(DATEDIF(L27,M27,"M")>12, "PKWT","PKWT"))))) -> PKWT | R27: Bachelor's Degree (S1) | S27: Psychology | T27: Human Resources | U27: Human Resources & General Affairs | V27: Staff | W27: Recruitment Staff | X27: =_xlfn.XLOOKUP(V27,Reference!$O:$O,Reference!$N:$N,"Tidak Ketemu") -> G11 | Y27: =IF(AND(G27="Female",H27="Married"),"TK/0",IF(H27="Married","K/"&I27,"TK/"&I27)) -> TK/0 | Z27: 991047804901327 | AA27: 68860886361 | AB27: 5887798353371 | AC27: BANK BCA | AD27: 2838186500 | AE27: 084900489759 | AF27: aulia.pratama@dumibumi.co.id | AG27: Jakarta, Indonesia
A28: 202044146 | B28: Dedi Hidayat | C28: 3682503993384988 | D28: 3784794058906662 | E28: Jakarta | F28: 35139 | G28: Male | H28: Married | I28: =MIN(COUNTIFS('Data Family'!A:A,A28,'Data Family'!F:F,"Child")+COUNTIFS('Data Family'!A:A,A28,'Data Family'!F:F,"<>Child",'Data Family'!J:J,"Housewife")+COUNTIFS('Data Family'!A:A,A28,'Data Family'!F:F,"<>Child",'Data Family'!J:J,"Unemployment"),3) -> 2 | J28: Islam | K28: B | L28: 44146 | O28: =IF(AND(M28<>"", M28<=TODAY(), N28=""), "End of Contract", "") | P28: =IF(OR(N28<>"", AND(M28<>"",M28<=TODAY())),"Non-Active","Active") -> Active | Q28: =IF(M28="","PKWTT",IF(DATEDIF(L28,M28,"M")>63,"PKWTT",IF(DATEDIF(L28,M28,"M")>60,"PKWT",IF(DATEDIF(L28,M28,"M")>36,"PKWT",IF(DATEDIF(L28,M28,"M")>12, "PKWT","PKWT"))))) -> PKWTT | R28: Bachelor's Degree (S1) | S28: Psychology | T28: Human Resources | U28: Human Resources & General Affairs | V28: Staff | W28: Recruitment Staff | X28: =_xlfn.XLOOKUP(V28,Reference!$O:$O,Reference!$N:$N,"Tidak Ketemu") -> G11 | Y28: =IF(AND(G28="Female",H28="Married"),"TK/0",IF(H28="Married","K/"&I28,"TK/"&I28)) -> K/2 | Z28: 504743316587698 | AA28: 13786953244 | AB28: 9580774748841 | AC28: BANK BCA | AD28: 3159217760 | AE28: 089449845925 | AF28: dedi.hidayat@dumibumi.co.id | AG28: Subang, Indonesia
A29: 202044084 | B29: Nisa Noor F. Halimah | C29: 2715407782759011 | D29: 0137335151447948 | E29: Karawang | F29: 35523 | G29: Female | H29: Single | I29: =MIN(COUNTIFS('Data Family'!A:A,A29,'Data Family'!F:F,"Child")+COUNTIFS('Data Family'!A:A,A29,'Data Family'!F:F,"<>Child",'Data Family'!J:J,"Housewife")+COUNTIFS('Data Family'!A:A,A29,'Data Family'!F:F,"<>Child",'Data Family'!J:J,"Unemployment"),3) -> 1 | J29: Islam | K29: O | L29: 44084 | O29: =IF(AND(M29<>"", M29<=TODAY(), N29=""), "End of Contract", "") | P29: =IF(OR(N29<>"", AND(M29<>"",M29<=TODAY())),"Non-Active","Active") -> Active | Q29: =IF(M29="","PKWTT",IF(DATEDIF(L29,M29,"M")>63,"PKWTT",IF(DATEDIF(L29,M29,"M")>60,"PKWT",IF(DATEDIF(L29,M29,"M")>36,"PKWT",IF(DATEDIF(L29,M29,"M")>12, "PKWT","PKWT"))))) -> PKWTT | R29: Bachelor's Degree (S1) | S29: Business Administration | T29: Human Resources | U29: Human Resources & General Affairs | V29: Staff | W29: HR Operations & General Affairs Staff | X29: =_xlfn.XLOOKUP(V29,Reference!$O:$O,Reference!$N:$N,"Tidak Ketemu") -> G11 | Y29: =IF(AND(G29="Female",H29="Married"),"TK/0",IF(H29="Married","K/"&I29,"TK/"&I29)) -> TK/1 | Z29: 073322594670363 | AA29: 08939101080 | AB29: 7377166617547 | AC29: BANK BCA | AD29: 5007694002 | AE29: 088932742962 | AF29: indah.wijaya@dumibumi.co.id | AG29: Bekasi, Indonesia
A30: 201642614 | B30: Andi Maulana | C30: 3496496638576534 | D30: 7959468099866577 | E30: Jakarta | F30: 35692 | G30: Male | H30: Married | I30: =MIN(COUNTIFS('Data Family'!A:A,A30,'Data Family'!F:F,"Child")+COUNTIFS('Data Family'!A:A,A30,'Data Family'!F:F,"<>Child",'Data Family'!J:J,"Housewife")+COUNTIFS('Data Family'!A:A,A30,'Data Family'!F:F,"<>Child",'Data Family'!J:J,"Unemployment"),3) -> 1 | J30: Islam | K30: A | L30: 45536 | M30: 46266 | O30: =IF(AND(M30<>"", M30<=TODAY(), N30=""), "End of Contract", "") | P30: =IF(OR(N30<>"", AND(M30<>"",M30<=TODAY())),"Non-Active","Active") -> Active | Q30: =IF(M30="","PKWTT",IF(DATEDIF(L30,M30,"M")>63,"PKWTT",IF(DATEDIF(L30,M30,"M")>60,"PKWT",IF(DATEDIF(L30,M30,"M")>36,"PKWT",IF(DATEDIF(L30,M30,"M")>12, "PKWT","PKWT"))))) -> PKWT | R30: Bachelor's Degree (S1) | S30: Communication | T30: Human Resources | U30: Human Resources & General Affairs | V30: Staff | W30: Employer Branding Staff | X30: =_xlfn.XLOOKUP(V30,Reference!$O:$O,Reference!$N:$N,"Tidak Ketemu") -> G11 | Y30: =IF(AND(G30="Female",H30="Married"),"TK/0",IF(H30="Married","K/"&I30,"TK/"&I30)) -> K/1 | Z30: 205474012330126 | AA30: 16523507644 | AB30: 2434280652279 | AC30: BANK BCA | AD30: 9927022456 | AE30: 086711232999 | AF30: andi.maulana@dumibumi.co.id | AG30: Subang, Indonesia
