Workbook
Name rgKategori: Referensi!$E$4:$E$128
Name rgPenghasilanMulai: Referensi!$F$4:$F$128
Name rgPenghasilanSampai: Referensi!$G$4:$G$128
Name rgTarifPajak: Referensi!$H$4:$H$128
Name tabPTKP: Referensi!$A$4:$C$11
Name tabStatusKategori: Referensi!#REF!

Sheet PPh21 GROSS
A1: PERHITUNGAN PPH21 TER 2026
A3: Nama | B3: Agus Wijaya
A4: Join Date | B4: 45569
A5: Status | B5: TK/0
A7: BULAN | B7: UPAH POKOK | C7: TUNJANGAN TETAP | D7: UANG MAKAN | E7: UANG TRANSPORT | F7: THR | G7: BONUS/INSENTIF | H7: LEMBUR | I7: P-JKK | J7: P-JKM | K7: P-BPJS KES | L7: K-JP | M7: K-JHT | N7: K-BPJS KES | O7: PENGHASULAN BRUTO | P7: TARIF PAJAK | Q7: PPH 21 | R7: TAKE HOME PAY
I8: 0.0127 | J8: 0.003 | K8: 0.04 | L8: 0.01 | M8: 0.02 | N8: 0.01
A9: Januari | B9: 4827725.5 | C9: 1609241.8 | D9: =18*19870 -> 357660 | E9: =18*15270 -> 274860 | I9: =(B9+C9)*$I$8 -> 81749.485 | J9: =(B9+C9)*$J$8 -> 19310.902 | K9: =$K$8 * MIN(B9+C9, 12000000) -> 257478.69 | L9: =$L$8 * MIN(B9+C9, 11086300) -> 64369.673 | M9: =(B9+C9)*$M$8 -> 128739.35 | N9: =$N$8*MIN(B9+C9,12000000) -> 64369.673 | O9: =SUM(B9:H9) -> 7069487.3 | P9: {=INDEX(rgTarifPajak,MATCH(1,(VLOOKUP($B$5,tabPTKP,3,FALSE)=rgKategori) *(O9>=rgPenghasilanMulai)*(O9<=rgPenghasilanSampai),0))} -> 0.0125 | Q9: =+P9*O9 -> 88368.592 | R9: =SUM(B9:H9)-SUM(L9:N9)-Q9 -> 6723640
A10: Februari | B10: 4827725.5 | C10: 1609241.8 | D10: =21*19870 -> 417270 | E10: =21*15270 -> 320670 | I10: =(B10+C10)*$I$8 -> 81749.485 | J10: =(B10+C10)*$J$8 -> 19310.902 | K10: =$K$8 * MIN(B10+C10, 12000000) -> 257478.69 | L10: =$L$8 * MIN(B10+C10, 11086300) -> 64369.673 | M10: =(B10+C10)*$M$8 -> 128739.35 | N10: =$N$8*MIN(B10+C10,12000000) -> 64369.673 | O10: =SUM(B10:H10) -> 7174907.3 | P10: {=INDEX(rgTarifPajak,MATCH(1,(VLOOKUP($B$5,tabPTKP,3,FALSE)=rgKategori) * (O10>=rgPenghasilanMulai) * (O10<=rgPenghasilanSampai), 0))} -> 0.0125 | Q10: =+P10*O10 -> 89686.342 | R10: =SUM(B10:H10)-SUM(L10:N10)-Q10 -> 6827742.3
A11: Maret | B11: 4827725.5 | C11: 1609241.8 | D11: =18*19870 -> 357660 | E11: =18*15270 -> 274860 | F11: =B11+C11 -> 6436967.3 | I11: =(B11+C11)*$I$8 -> 81749.485 | J11: =(B11+C11)*$J$8 -> 19310.902 | K11: =$K$8 * MIN(B11+C11, 12000000) -> 257478.69 | L11: =$L$8 * MIN(B11+C11, 11086300) -> 64369.673 | M11: =(B11+C11)*$M$8 -> 128739.35 | N11: =$N$8*MIN(B11+C11,12000000) -> 64369.673 | O11: =SUM(B11:H11) -> 13506455 | P11: {=INDEX(rgTarifPajak,MATCH(1,(VLOOKUP($B$5,tabPTKP,3,FALSE)=rgKategori) * (O11>=rgPenghasilanMulai) * (O11<=rgPenghasilanSampai), 0))} -> 0.05 | Q11: =+P11*O11 -> 675322.73 | R11: =SUM(B11:H11)-SUM(L11:N11)-Q11 -> 12573653
A12: April | B12: 4827725.5 | C12: 1609241.8 | D12: =18*19870 -> 357660 | E12: =18*15270 -> 274860 | I12: =(B12+C12)*$I$8 -> 81749.485 | J12: =(B12+C12)*$J$8 -> 19310.902 | K12: =$K$8 * MIN(B12+C12, 12000000) -> 257478.69 | L12: =$L$8 * MIN(B12+C12, 11086300) -> 64369.673 | M12: =(B12+C12)*$M$8 -> 128739.35 | N12: =$N$8*MIN(B12+C12,12000000) -> 64369.673 | O12: =SUM(B12:H12) -> 7069487.3 | P12: {=INDEX(rgTarifPajak,MATCH(1,(VLOOKUP($B$5,tabPTKP,3,FALSE)=rgKategori) * (O12>=rgPenghasilanMulai) * (O12<=rgPenghasilanSampai), 0))} -> 0.0125 | Q12: =+P12*O12 -> 88368.592 | R12: =SUM(B12:H12)-SUM(L12:N12)-Q12 -> 6723640
A13: Mei | B13: 4827725.5 | C13: 1609241.8 | D13: =20*19870 -> 397400 | E13: =20*15270 -> 305400 | I13: =(B13+C13)*$I$8 -> 81749.485 | J13: =(B13+C13)*$J$8 -> 19310.902 | K13: =$K$8 * MIN(B13+C13, 12000000) -> 257478.69 | L13: =$L$8 * MIN(B13+C13, 11086300) -> 64369.673 | M13: =(B13+C13)*$M$8 -> 128739.35 | N13: =$N$8*MIN(B13+C13,12000000) -> 64369.673 | O13: =SUM(B13:H13) -> 7139767.3 | P13: {=INDEX(rgTarifPajak,MATCH(1,(VLOOKUP($B$5,tabPTKP,3,FALSE)=rgKategori) * (O13>=rgPenghasilanMulai) * (O13<=rgPenghasilanSampai), 0))} -> 0.0125 | Q13: =+P13*O13 -> 89247.092 | R13: =SUM(B13:H13)-SUM(L13:N13)-Q13 -> 6793041.5
A14: Juni | B14: 4827725.5 | C14: 1609241.8 | D14: =18*19870 -> 357660 | E14: =18*15270 -> 274860 | I14: =(B14+C14)*$I$8 -> 81749.485 | J14: =(B14+C14)*$J$8 -> 19310.902 | K14: =$K$8 * MIN(B14+C14, 12000000) -> 257478.69 | L14: =$L$8 * MIN(B14+C14, 11086300) -> 64369.673 | M14: =(B14+C14)*$M$8 -> 128739.35 | N14: =$N$8*MIN(B14+C14,12000000) -> 64369.673 | O14: =SUM(B14:H14) -> 7069487.3 | P14: {=INDEX(rgTarifPajak,MATCH(1,(VLOOKUP($B$5,tabPTKP,3,FALSE)=rgKategori) * (O14>=rgPenghasilanMulai) * (O14<=rgPenghasilanSampai), 0))} -> 0.0125 | Q14: =+P14*O14 -> 88368.592 | R14: =SUM(B14:H14)-SUM(L14:N14)-Q14 -> 6723640
A15: Juli | B15: 4827725.5 | C15: 1609241.8 | D15: =20*19870 -> 397400 | E15: =20*15270 -> 305400 | H15: 353475.08 | I15: =(B15+C15)*$I$8 -> 81749.485 | J15: =(B15+C15)*$J$8 -> 19310.902 | K15: =$K$8 * MIN(B15+C15, 12000000) -> 257478.69 | L15: =$L$8 * MIN(B15+C15, 11086300) -> 64369.673 | M15: =(B15+C15)*$M$8 -> 128739.35 | N15: =$N$8*MIN(B15+C15,12000000) -> 64369.673 | O15: =SUM(B15:H15) -> 7493242.4 | P15: {=INDEX(rgTarifPajak,MATCH(1,(VLOOKUP($B$5,tabPTKP,3,FALSE)=rgKategori) * (O15>=rgPenghasilanMulai) * (O15<=rgPenghasilanSampai), 0))} -> 0.0125 | Q15: =+P15*O15 -> 93665.53 | R15: =SUM(B15:H15)-SUM(L15:N15)-Q15 -> 7142098.2
A16: Agustus | B16: 4827725.5 | C16: 1609241.8 | D16: =21*19870 -> 417270 | E16: =21*15270 -> 320670 | I16: =(B16+C16)*$I$8 -> 81749.485 | J16: =(B16+C16)*$J$8 -> 19310.902 | K16: =$K$8 * MIN(B16+C16, 12000000) -> 257478.69 | L16: =$L$8 * MIN(B16+C16, 11086300) -> 64369.673 | M16: =(B16+C16)*$M$8 -> 128739.35 | N16: =$N$8*MIN(B16+C16,12000000) -> 64369.673 | O16: =SUM(B16:H16) -> 7174907.3 | P16: {=INDEX(rgTarifPajak,MATCH(1,(VLOOKUP($B$5,tabPTKP,3,FALSE)=rgKategori) * (O16>=rgPenghasilanMulai) * (O16<=rgPenghasilanSampai), 0))} -> 0.0125 | Q16: =+P16*O16 -> 89686.342 | R16: =SUM(B16:H16)-SUM(L16:N16)-Q16 -> 6827742.3
A17: September | B17: 4827725.5 | C17: 1609241.8 | D17: =20*19870 -> 397400 | E17: =20*15270 -> 305400 | I17: =(B17+C17)*$I$8 -> 81749.485 | J17: =(B17+C17)*$J$8 -> 19310.902 | K17: =$K$8 * MIN(B17+C17, 12000000) -> 257478.69 | L17: =$L$8 * MIN(B17+C17, 11086300) -> 64369.673 | M17: =(B17+C17)*$M$8 -> 128739.35 | N17: =$N$8*MIN(B17+C17,12000000) -> 64369.673 | O17: =SUM(B17:H17) -> 7139767.3 | P17: {=INDEX(rgTarifPajak,MATCH(1,(VLOOKUP($B$5,tabPTKP,3,FALSE)=rgKategori) * (O17>=rgPenghasilanMulai) * (O17<=rgPenghasilanSampai), 0))} -> 0.0125 | Q17: =+P17*O17 -> 89247.092 | R17: =SUM(B17:H17)-SUM(L17:N17)-Q17 -> 6793041.5
A18: Oktober | B18: 4827725.5 | C18: 1609241.8 | D18: =22*19870 -> 437140 | E18: =22*15270 -> 335940 | I18: =(B18+C18)*$I$8 -> 81749.485 | J18: =(B18+C18)*$J$8 -> 19310.902 | K18: =$K$8 * MIN(B18+C18, 12000000) -> 257478.69 | L18: =$L$8 * MIN(B18+C18, 11086300) -> 64369.673 | M18: =(B18+C18)*$M$8 -> 128739.35 | N18: =$N$8*MIN(B18+C18,12000000) -> 64369.673 | O18: =SUM(B18:H18) -> 7210047.3 | P18: {=INDEX(rgTarifPajak,MATCH(1,(VLOOKUP($B$5,tabPTKP,3,FALSE)=rgKategori) * (O18>=rgPenghasilanMulai) * (O18<=rgPenghasilanSampai), 0))} -> 0.0125 | Q18: =+P18*O18 -> 90125.592 | R18: =SUM(B18:H18)-SUM(L18:N18)-Q18 -> 6862443
A19: November | B19: 4827725.5 | C19: 1609241.8 | D19: =22*19870 -> 437140 | E19: =22*15270 -> 335940 | I19: =(B19+C19)*$I$8 -> 81749.485 | J19: =(B19+C19)*$J$8 -> 19310.902 | K19: =$K$8 * MIN(B19+C19, 12000000) -> 257478.69 | L19: =$L$8 * MIN(B19+C19, 11086300) -> 64369.673 | M19: =(B19+C19)*$M$8 -> 128739.35 | N19: =$N$8*MIN(B19+C19,12000000) -> 64369.673 | O19: =SUM(B19:H19) -> 7210047.3 | P19: {=INDEX(rgTarifPajak,MATCH(1,(VLOOKUP($B$5,tabPTKP,3,FALSE)=rgKategori) * (O19>=rgPenghasilanMulai) * (O19<=rgPenghasilanSampai), 0))} -> 0.0125 | Q19: =+P19*O19 -> 90125.592 | R19: =SUM(B19:H19)-SUM(L19:N19)-Q19 -> 6862443
A20: Desember | B20: 4827725.5 | C20: 1609241.8 | D20: =21*19870 -> 417270 | E20: =21*15270 -> 320670 | I20: =(B20+C20)*$I$8 -> 81749.485 | J20: =(B20+C20)*$J$8 -> 19310.902 | K20: =$K$8 * MIN(B20+C20, 12000000) -> 257478.69 | L20: =$L$8 * MIN(B20+C20, 11086300) -> 64369.673 | M20: =(B20+C20)*$M$8 -> 128739.35 | N20: =$N$8*MIN(B20+C20,12000000) -> 64369.673 | O20: =SUM(B20:H20) -> 7174907.3 | P20: 0 | Q20: 0 | R20: =SUM(B20:H20)-SUM(L20:N20)-Q20 -> 6917428.6
A21: Jumlah | B21: =SUM(B9:B20) -> 57932706 | C21: =SUM(C9:C20) -> 19310902 | D21: =SUM(D9:D20) -> 4748930 | E21: =SUM(E9:E20) -> 3649530 | F21: =SUM(F9:F20) -> 6436967.3 | G21: =SUM(G9:G20) -> 0 | H21: =SUM(H9:H20) -> 353475.08 | I21: =SUM(I9:I20) -> 980993.82 | ... N21: =SUM(N9:N20) -> 772436.08 | O21: =SUM(B21:K21) -> 96734979 | P21: 0 | Q21: 0 | R21: =SUM(R9:R20) -> 87770554
A23: PPH21 Desember 2026 | H23: FORMULA
A24: Penghasilan Bruto Setahun | F24: =O21 -> 96734979 | H24: 1
A25: Pengurang | H25: (-)
A26: • Biaya Jabatan max Rp. 6JT | C26: 0.05 | F26: =MIN(6000000,5%*F24) -> 4836749 | H26: 2
A27: • Iuran JP | C27: =L8 -> 0.01 | F27: =L21 -> 772436.08 | H27: 3
A28: • Iuran JHT | C28: =M8 -> 0.02 | F28: =M21 -> 1544872.2 | H28: 4
F29: =SUM(F26:F28) -> 7154057.2 | H29: 5=2+3+4
A30: Penghasilan Netto Setahun | F30: =F24-F29 -> 89580922 | H30: 6=1-5
A31: Penghasilan Tidak Kena Pajak Setahun | F31: =VLOOKUP($B$5,tabPTKP,2,FALSE) -> 54000000 | H31: 7
A32: Penghasilan Kena Pajak Setahun | F32: =ROUNDDOWN(F30-F31,-3) -> 35580000 | H32: 8
A34: PPH 21 Terutang Setahun
A35: 0.05 | B35: x | C35: =MIN(F32,Referensi!M4) -> 35580000 | F35: =A35*C35 -> 1779000 | H35: 9
A36: 0.15 | B36: x | C36: =MIN(Referensi!M5,MAX(F32-Referensi!M4,0)) -> 0 | F36: =A36*C36 -> 0 | H36: 10
A37: 0.25 | B37: x | C37: =MIN(Referensi!M5,MAX(F32-Referensi!M4-Referensi!M5,0)) -> 0 | F37: =A37*C37 -> 0 | H37: 11
A38: 0.3 | B38: x | C38: =MIN(Referensi!M5,MAX(F32-Referensi!M4-Referensi!M5-Referensi!M6,0)) -> 0 | F38: =A38*C38 -> 0 | H38: 12
A39: 0.35 | B39: x | C39: =MIN(Referensi!M5,MAX(F32-Referensi!M4-Referensi!M5-Referensi!M6-Referensi!M7,0)) -> 0 | F39: =A39*C39 -> 0 | H39: 13
F40: =SUM(F35:F39) -> 1779000 | H40: 14=9+10+11+12+13
A41: PPH 21 Sudah Dibayarkan sd November 2026 | F41: =SUM(Q9:Q19) -> 1572212.1 | H41: 15
A42: PPH21 Dipotong Bulan Desember 2026 | F42: =F40-F41 -> 206787.91 | H42: 16=14-15
A44: Source: Portofolio/Payroll Management System/Potongan

Sheet PPh21 GROSS-UP
A2: PERHITUNGAN PPH21 TER 2026
A3: PT. DUMI BUMI TBK
A5: Nama | B5: Bebeb
A6: Status | B6: TK/0
A7: Jabatan | B7: Staff IT
A9: BULAN | B9: UPAH POKOK | C9: TUNJANGAN | D9: THR | E9: BONUS/INSENTIF | F9: LEMBUR | G9: TUNJANGAN PPH21 | H9: JKK | I9: JKM | J9: KES PRS | K9: JP | L9: JHT | M9: KES KRY | N9: PENGHASULAN BRUTO | O9: TARIF PAJAK | P9: PPH 21 | Q9: TAKE HOME PAY
H10: 0.0024 | I10: 0.003 | J10: 0.04 | K10: 0.01 | L10: 0.02 | M10: 0.01
A11: Januari | B11: 0 | G11: =P11 -> 0 | H11: =H$10*$B11 -> 0 | I11: =I$10*$B11 -> 0 | J11: =J$10*MIN($B11,12000000) -> 0 | K11: =K$10*MIN($B11,10547400) -> 0 | L11: =L$10*$B11 -> 0 | M11: =M$10*MIN($B11,12000000) -> 0 | N11: =SUM(B11:J11) -> 0 | O11: {=INDEX(rgTarifPajak, MATCH(1, (VLOOKUP($B$6,tabPTKP,3,FALSE)=rgKategori) * (N11>=rgPenghasilanMulai) * (N11<=rgPenghasilanSampai), 0))} -> 0 | P11: =+O11*N11 -> 0 | Q11: =SUM(B11:G11)-SUM(K11:M11)-P11 -> 0
A12: Februari | B12: 0 | G12: =P12 -> 0 | H12: =H$10*$B12 -> 0 | I12: =I$10*$B12 -> 0 | J12: =J$10*MIN($B12,12000000) -> 0 | K12: =K$10*MIN($B12,10547400) -> 0 | L12: =L$10*$B12 -> 0 | M12: =M$10*MIN($B12,12000000) -> 0 | N12: =SUM(B12:J12) -> 0 | O12: {=INDEX(rgTarifPajak, MATCH(1, (VLOOKUP($B$6,tabPTKP,3,FALSE)=rgKategori) * (N12>=rgPenghasilanMulai) * (N12<=rgPenghasilanSampai), 0))} -> 0 | P12: =+O12*N12 -> 0 | Q12: =SUM(B12:G12)-SUM(K12:M12)-P12 -> 0
A13: Maret | B13: 0 | G13: =P13 -> 0 | H13: =H$10*$B13 -> 0 | I13: =I$10*$B13 -> 0 | J13: =J$10*MIN($B13,12000000) -> 0 | K13: =K$10*MIN($B13,10547400) -> 0 | L13: =L$10*$B13 -> 0 | M13: =M$10*MIN($B13,12000000) -> 0 | N13: =SUM(B13:J13) -> 0 | O13: {=INDEX(rgTarifPajak, MATCH(1, (VLOOKUP($B$6,tabPTKP,3,FALSE)=rgKategori) * (N13>=rgPenghasilanMulai) * (N13<=rgPenghasilanSampai), 0))} -> 0 | P13: =+O13*N13 -> 0 | Q13: =SUM(B13:G13)-SUM(K13:M13)-P13 -> 0
A14: April | B14: 0 | G14: =P14 -> 0 | H14: =H$10*$B14 -> 0 | I14: =I$10*$B14 -> 0 | J14: =J$10*MIN($B14,12000000) -> 0 | K14: =K$10*MIN($B14,10547400) -> 0 | L14: =L$10*$B14 -> 0 | M14: =M$10*MIN($B14,12000000) -> 0 | N14: =SUM(B14:J14) -> 0 | O14: {=INDEX(rgTarifPajak, MATCH(1, (VLOOKUP($B$6,tabPTKP,3,FALSE)=rgKategori) * (N14>=rgPenghasilanMulai) * (N14<=rgPenghasilanSampai), 0))} -> 0 | P14: =+O14*N14 -> 0 | Q14: =SUM(B14:G14)-SUM(K14:M14)-P14 -> 0
A15: Mei | B15: 0 | G15: =P15 -> 0 | H15: =H$10*$B15 -> 0 | I15: =I$10*$B15 -> 0 | J15: =J$10*MIN($B15,12000000) -> 0 | K15: =K$10*MIN($B15,10547400) -> 0 | L15: =L$10*$B15 -> 0 | M15: =M$10*MIN($B15,12000000) -> 0 | N15: =SUM(B15:J15) -> 0 | O15: {=INDEX(rgTarifPajak, MATCH(1, (VLOOKUP($B$6,tabPTKP,3,FALSE)=rgKategori) * (N15>=rgPenghasilanMulai) * (N15<=rgPenghasilanSampai), 0))} -> 0 | P15: =+O15*N15 -> 0 | Q15: =SUM(B15:G15)-SUM(K15:M15)-P15 -> 0
A16: Juni | B16: 0 | G16: =P16 -> 0 | H16: =H$10*$B16 -> 0 | I16: =I$10*$B16 -> 0 | J16: =J$10*MIN($B16,12000000) -> 0 | K16: =K$10*MIN($B16,10547400) -> 0 | L16: =L$10*$B16 -> 0 | M16: =M$10*MIN($B16,12000000) -> 0 | N16: =SUM(B16:J16) -> 0 | O16: {=INDEX(rgTarifPajak, MATCH(1, (VLOOKUP($B$6,tabPTKP,3,FALSE)=rgKategori) * (N16>=rgPenghasilanMulai) * (N16<=rgPenghasilanSampai), 0))} -> 0 | P16: =+O16*N16 -> 0 | Q16: =SUM(B16:G16)-SUM(K16:M16)-P16 -> 0
A17: Juli | B17: 0 | G17: =P17 -> 0 | H17: =H$10*$B17 -> 0 | I17: =I$10*$B17 -> 0 | J17: =J$10*MIN($B17,12000000) -> 0 | K17: =K$10*MIN($B17,10547400) -> 0 | L17: =L$10*$B17 -> 0 | M17: =M$10*MIN($B17,12000000) -> 0 | N17: =SUM(B17:J17) -> 0 | O17: {=INDEX(rgTarifPajak, MATCH(1, (VLOOKUP($B$6,tabPTKP,3,FALSE)=rgKategori) * (N17>=rgPenghasilanMulai) * (N17<=rgPenghasilanSampai), 0))} -> 0 | P17: =+O17*N17 -> 0 | Q17: =SUM(B17:G17)-SUM(K17:M17)-P17 -> 0
A18: Agustus | B18: 0 | G18: =P18 -> 0 | H18: =H$10*$B18 -> 0 | I18: =I$10*$B18 -> 0 | J18: =J$10*MIN($B18,12000000) -> 0 | K18: =K$10*MIN($B18,10547400) -> 0 | L18: =L$10*$B18 -> 0 | M18: =M$10*MIN($B18,12000000) -> 0 | N18: =SUM(B18:J18) -> 0 | O18: {=INDEX(rgTarifPajak, MATCH(1, (VLOOKUP($B$6,tabPTKP,3,FALSE)=rgKategori) * (N18>=rgPenghasilanMulai) * (N18<=rgPenghasilanSampai), 0))} -> 0 | P18: =+O18*N18 -> 0 | Q18: =SUM(B18:G18)-SUM(K18:M18)-P18 -> 0
A19: September | B19: 0 | G19: =P19 -> 0 | H19: =H$10*$B19 -> 0 | I19: =I$10*$B19 -> 0 | J19: =J$10*MIN($B19,12000000) -> 0 | K19: =K$10*MIN($B19,10547400) -> 0 | L19: =L$10*$B19 -> 0 | M19: =M$10*MIN($B19,12000000) -> 0 | N19: =SUM(B19:J19) -> 0 | O19: {=INDEX(rgTarifPajak, MATCH(1, (VLOOKUP($B$6,tabPTKP,3,FALSE)=rgKategori) * (N19>=rgPenghasilanMulai) * (N19<=rgPenghasilanSampai), 0))} -> 0 | P19: =+O19*N19 -> 0 | Q19: =SUM(B19:G19)-SUM(K19:M19)-P19 -> 0
A20: Oktober | B20: 0 | G20: =P20 -> 0 | H20: =H$10*$B20 -> 0 | I20: =I$10*$B20 -> 0 | J20: =J$10*MIN($B20,12000000) -> 0 | K20: =K$10*MIN($B20,10547400) -> 0 | L20: =L$10*$B20 -> 0 | M20: =M$10*MIN($B20,12000000) -> 0 | N20: =SUM(B20:J20) -> 0 | O20: {=INDEX(rgTarifPajak, MATCH(1, (VLOOKUP($B$6,tabPTKP,3,FALSE)=rgKategori) * (N20>=rgPenghasilanMulai) * (N20<=rgPenghasilanSampai), 0))} -> 0 | P20: =+O20*N20 -> 0 | Q20: =SUM(B20:G20)-SUM(K20:M20)-P20 -> 0
A21: November | B21: 0 | G21: =P21 -> 0 | H21: =H$10*$B21 -> 0 | I21: =I$10*$B21 -> 0 | J21: =J$10*MIN($B21,12000000) -> 0 | K21: =K$10*MIN($B21,10547400) -> 0 | L21: =L$10*$B21 -> 0 | M21: =M$10*MIN($B21,12000000) -> 0 | N21: =SUM(B21:J21) -> 0 | O21: {=INDEX(rgTarifPajak, MATCH(1, (VLOOKUP($B$6,tabPTKP,3,FALSE)=rgKategori) * (N21>=rgPenghasilanMulai) * (N21<=rgPenghasilanSampai), 0))} -> 0 | P21: =+O21*N21 -> 0 | Q21: =SUM(B21:G21)-SUM(K21:M21)-P21 -> 0
A22: Desember | B22: 0 | G22: =P22 -> -2834645.7 | H22: =H$10*$B22 -> 0 | I22: =I$10*$B22 -> 0 | J22: =J$10*MIN($B22,12000000) -> 0 | K22: =K$10*MIN($B22,10547400) -> 0 | L22: =L$10*$B22 -> 0 | M22: =M$10*MIN($B22,12000000) -> 0 | N22: =SUM(B22:J22) -> -2834645.7 | P22: =E45 -> -2834645.7 | Q22: =SUM(B22:G22)-SUM(K22:M22)-P22 -> 0
A23: Jumlah | B23: =SUM(B11:B22) -> 0 | C23: =SUM(C11:C22) -> 0 | D23: =SUM(D11:D22) -> 0 | E23: =SUM(E11:E22) -> 0 | F23: =SUM(F11:F22) -> 0 | G23: =SUM(G11:G22) -> -2834645.7 | H23: =SUM(H11:H22) -> 0 | I23: =SUM(I11:I22) -> 0 | ... M23: =SUM(M11:M22) -> 0 | N23: =SUM(B23:J23) -> -2834645.7 | P23: =SUM(P11:P22) -> -2834645.7 | Q23: =SUM(Q11:Q22) -> 0
A26: PPH21 Desember 2025 | F26: FORMULA
A27: Penghasilan Bruto Setahun | E27: =N23 -> -2834645.7 | F27: 1
A28: Pengurang
A29: • Biaya Jabatan | D29: =MIN(6000000,5%*N23) -> -141732.28 | F29: 2
A30: • Iuran JP | C30: =K10 -> 0.01 | D30: =K23 -> 0 | F30: 3
A31: • Iuran JHT | C31: =L10 -> 0.02 | D31: =L23 -> 0 | F31: 4
E32: =SUM(D29:D31) -> -141732.28 | F32: 5=2+3+4
A33: Penghasilan Netto Setahun | E33: =E27-E32 -> -2692913.4 | F33: 6=1-5
A34: Penghasilan Tidak Kena Pajak Setahun | D34: =VLOOKUP($B$6,tabPTKP,2,FALSE) -> 54000000 | F34: 7
A35: Penghasilan Kena Pajak Setahun | E35: =E33-D34 -> -56692913 | F35: 8
A37: PPH 21 Terutang Setahun
A38: 0.05 | B38: x | C38: =MIN(E35,Referensi!M4) -> -56692913 | D38: =A38*C38 -> -2834645.7 | F38: 9
A39: 0.15 | B39: x | C39: =MIN(Referensi!M5,MAX(E35-Referensi!M4,0)) -> 0 | D39: =A39*C39 -> 0 | F39: 10
A40: 0.25 | B40: x | C40: =MIN(Referensi!M5,MAX(E35-Referensi!M4-Referensi!M5,0)) -> 0 | D40: =A40*C40 -> 0 | F40: 11
A41: 0.3 | B41: x | C41: =MIN(Referensi!M5,MAX(E35-Referensi!M4-Referensi!M5-Referensi!M6,0)) -> 0 | D41: =A41*C41 -> 0 | F41: 12
A42: 0.35 | B42: x | C42: =MIN(Referensi!M5,MAX(E35-Referensi!M4-Referensi!M5-Referensi!M6-Referensi!M7,0)) -> 0 | D42: =A42*C42 -> 0 | F42: 13
E43: =SUM(D38:D42) -> -2834645.7 | F43: 14=9+10+11+12+13
A44: PPH 21 Sudah Dibayarkan sd November 2025 | E44: =SUM(P11:P21) -> 0 | F44: 15
A45: PPH21 Dipotong Bulan Desember 2025 | E45: =E43-E44 -> -2834645.7 | F45: 16=14-15

Sheet Referensi
A2: PENGHASILAN TIDAK KENA PAJAK (PTKP) | E2: TABEL TARIF TER A,B,C | J2: TARIF PAJAK PASAL 17 PPH
A3: Status | B3: PTKP | C3: Kategori | E3: Kategori | F3: Penghasilan Mulai | G3: Penghasilan Sampai | H3: Tarif Efektif Bulanan | J3: Pajak | K3: Dari | L3: Sampai | M3: Rentang
A4: TK/0 | B4: 54000000 | C4: Kategori A | E4: Kategori A | F4: 0 | G4: 5400000 | H4: 0 | J4: 0.05 | K4: 0 | L4: 60000000 | M4: =L4-K4 -> 60000000
A5: TK/1 | B5: 58500000 | C5: Kategori A | E5: Kategori A | F5: =+G4 -> 5400000 | G5: 5650000 | H5: 0.0025 | J5: 0.15 | K5: 60000000 | L5: 250000000 | M5: =L5-K5 -> 190000000
A6: K/0 | B6: 58500000 | C6: Kategori A | E6: Kategori A | F6: =+G5 -> 5650000 | G6: 5950000 | H6: 0.005 | J6: 0.25 | K6: 250000000 | L6: 500000000 | M6: =L6-K6 -> 250000000
A7: TK/2 | B7: 63000000 | C7: Kategori B | E7: Kategori A | F7: =+G6 -> 5950000 | G7: 6300000 | H7: 0.0075 | J7: 0.3 | K7: 500000000 | L7: 5000000000 | M7: =L7-K7 -> 4500000000
A8: TK/3 | B8: 67500000 | C8: Kategori B | E8: Kategori A | F8: =+G7 -> 6300000 | G8: 6750000 | H8: 0.01 | J8: 0.35 | K8: 5000000000 | L8: 99999999999 | M8: =L8-K8 -> 94999999999
A9: K/1 | B9: 63000000 | C9: Kategori B | E9: Kategori A | F9: =+G8 -> 6750000 | G9: 7500000 | H9: 0.0125
A10: K/2 | B10: 67500000 | C10: Kategori B | E10: Kategori A | F10: =+G9 -> 7500000 | G10: 8550000 | H10: 0.015
A11: K/3 | B11: 72000000 | C11: Kategori C | E11: Kategori A | F11: =+G10 -> 8550000 | G11: 9650000 | H11: 0.0175
E12: Kategori A | F12: =+G11 -> 9650000 | G12: 10050000 | H12: 0.02
E13: Kategori A | F13: =+G12 -> 10050000 | G13: 10350000 | H13: 0.0225
E14: Kategori A | F14: =+G13 -> 10350000 | G14: 10700000 | H14: 0.025
E15: Kategori A | F15: =+G14 -> 10700000 | G15: 11050000 | H15: 0.03
E16: Kategori A | F16: =+G15 -> 11050000 | G16: 11600000 | H16: 0.035
E17: Kategori A | F17: =+G16 -> 11600000 | G17: 12500000 | H17: 0.04
E18: Kategori A | F18: =+G17 -> 12500000 | G18: 13750000 | H18: 0.05
E19: Kategori A | F19: =+G18 -> 13750000 | G19: 15100000 | H19: 0.06
E20: Kategori A | F20: =+G19 -> 15100000 | G20: 16950000 | H20: 0.07
E21: Kategori A | F21: =+G20 -> 16950000 | G21: 19750000 | H21: 0.08
E22: Kategori A | F22: =+G21 -> 19750000 | G22: 24150000 | H22: 0.09
E23: Kategori A | F23: =+G22 -> 24150000 | G23: 26450000 | H23: 0.1
... E47: Kategori A | F47: =+G46 -> 1400000000 | G47: 99999999999 | H47: 0.34
E48: Kategori B | F48: 0 | G48: 6200000 | H48: 0
E49: Kategori B | F49: =+G48 -> 6200000 | G49: 6500000 | H49: 0.0025
E50: Kategori B | F50: =+G49 -> 6500000 | G50: 6850000 | H50: 0.005
E51: Kategori B | F51: =+G50 -> 6850000 | G51: 7300000 | H51: 0.0075
E52: Kategori B | F52: =+G51 -> 7300000 | G52: 9200000 | H52: 0.01
E53: Kategori B | F53: =+G52 -> 9200000 | G53: 10750000 | H53: 0.015
E54: Kategori B | F54: =+G53 -> 10750000 | G54: 11250000 | H54: 0.02
E55: Kategori B | F55: =+G54 -> 11250000 | G55: 11600000 | H55: 0.025
E56: Kategori B | F56: =+G55 -> 11600000 | G56: 12600000 | H56: 0.03
E57: Kategori B | F57: =+G56 -> 12600000 | G57: 13600000 | H57: 0.04
E58: Kategori B | F58: =+G57 -> 13600000 | G58: 14950000 | H58: 0.05
E59: Kategori B | F59: =+G58 -> 14950000 | G59: 16400000 | H59: 0.06
E60: Kategori B | F60: =+G59 -> 16400000 | G60: 18450000 | H60: 0.07
... E87: Kategori B | F87: =+G86 -> 1405000000 | G87: 99999999999 | H87: 0.34
E88: Kategori C | F88: 0 | G88: 6600000 | H88: 0
E89: Kategori C | F89: =+G88 -> 6600000 | G89: 6950000 | H89: 0.0025
E90: Kategori C | F90: =+G89 -> 6950000 | G90: 7350000 | H90: 0.005
...
